Workbook

Sheet RIO DE JANEIRO
A1: CONSOLIDADO DE ESTOQUE — RIO DE JANEIRO
A2: Itens únicos (sem repetição entre abas — prioridade A→B→C). Coluna Categoria identifica Ferramentaria ou SSO.
A4: Categoria | B4: Código | C4: Descrição | D4: Unidade | E4: Aba origem | F4: Quantidade
A5: Ferramentaria | B5: 1000032 | C5: ALICATE DE BICO 6 | D5: PÇ | E5: A | F5: =SUMIF(a!$B:$B,$B5,a!$F:$F) -> 40
A6: Ferramentaria | B6: 1000033 | C6: ALICATE DE CORTE 6 | D6: PÇ | E6: A | F6: =SUMIF(a!$B:$B,$B6,a!$F:$F) -> 11
A7: Ferramentaria | B7: 1001306 | C7: ALICATE DE GRIMPAR RJ11 / RJ45 | D7: UND | E7: A | F7: =SUMIF(a!$B:$B,$B7,a!$F:$F) -> 53
A8: Ferramentaria | B8: 1000036 | C8: ALICATE DE PRESSÃO RG6 | D8: PÇ | E8: A | F8: =SUMIF(a!$B:$B,$B8,a!$F:$F) -> 50
A9: Ferramentaria | B9: 1000039 | C9: ALICATE UNIVERSAL 8 | D9: PÇ | E9: A | F9: =SUMIF(a!$B:$B,$B9,a!$F:$F) -> 75
A10: Ferramentaria | B10: 1001455 | C10: APLICADOR DE COLA QUENTE | D10: UN | E10: A | F10: =SUMIF(a!$B:$B,$B10,a!$F:$F) -> 103
A11: Ferramentaria | B11: 1000048 | C11: BADISCO DIGITAL GANDOLA | D11: PÇ | E11: A | F11: =SUMIF(a!$B:$B,$B11,a!$F:$F) -> 198
A12: Ferramentaria | B12: 1001702 | C12: BROCA CHATA MADEIRA 10 MM X 150 MM | D12: UN | E12: A | F12: =SUMIF(a!$B:$B,$B12,a!$F:$F) -> 5
A13: Ferramentaria | B13: 1001701 | C13: BROCA CHATA MADEIRA 8 MM X 150 MM | D13: UN | E13: A | F13: =SUMIF(a!$B:$B,$B13,a!$F:$F) -> 5
A14: Ferramentaria | B14: 1001680 | C14: BROCA DE WIDEA 10MM X 400MM (LONGA) | D14: PÇ | E14: A | F14: =SUMIF(a!$B:$B,$B14,a!$F:$F) -> 43
A15: Ferramentaria | B15: 1008890 | C15: CAMERA SONDA ENDOSCOPICA- 5 M | D15: UN | E15: A | F15: =SUMIF(a!$B:$B,$B15,a!$F:$F) -> 6
A16: Ferramentaria | B16: 1001289 | C16: CANETA DETECTORA DE TENSÃO 90 - 100 | D16: UND | E16: A | F16: =SUMIF(a!$B:$B,$B16,a!$F:$F) -> 125
... A37: Ferramentaria | B37: 1001476 | C37: TESTADOR DE CABO DE REDE LAN (ETHER) | D37: UN | E37: A | F37: =SUMIF(a!$B:$B,$B37,a!$F:$F) -> 164
A38: Ferramentaria | B38: 1000037 | C38: ALICATE DECAPADOR DE FIBRA OPTICA | D38: PÇ | E38: B | F38: =SUMIF(b!$B:$B,$B38,b!$F:$F) -> 173
A39: Ferramentaria | B39: 1000049 | C39: BALDE DE LONA | D39: PÇ | E39: B | F39: =SUMIF(b!$B:$B,$B39,b!$F:$F) -> 19
A40: Ferramentaria | B40: 1001712 | C40: BROCA CHATA MADEIRA 6MM X 150MM | D40: UN | E40: B | F40: =SUMIF(b!$B:$B,$B40,b!$F:$F) -> 5
A41: Ferramentaria | B41: 1001939 | C41: CAVALETE SUPORTE PARA BOBINA | D41: UN | E41: B | F41: =SUMIF(b!$B:$B,$B41,b!$F:$F) -> 10
A42: Ferramentaria | B42: 1000183 | C42: CHAVE DE FENDA GRANDE | D42: UND | E42: B | F42: =SUMIF(b!$B:$B,$B42,b!$F:$F) -> 64
A43: Ferramentaria | B43: 1000185 | C43: CHAVE DE FENDA PEQUENA | D43: UND | E43: B | F43: =SUMIF(b!$B:$B,$B43,b!$F:$F) -> 88
A44: Ferramentaria | B44: 1000197 | C44: CHAVE PHILIPS MEDIA | D44: UND | E44: B | F44: =SUMIF(b!$B:$B,$B44,b!$F:$F) -> 54
A45: Ferramentaria | B45: 1000319 | C45: LANTERNA | D45: UND | E45: B | F45: =SUMIF(b!$B:$B,$B45,b!$F:$F) -> 56
A46: Ferramentaria | B46: 1002108 | C46: TESOURÃO CORTA VERGALHÃO 30 | D46: UN | E46: B | F46: =SUMIF(b!$B:$B,$B46,b!$F:$F) -> 13
A47: Ferramentaria | B47: 1001719 | C47: ALICATE COMPRESSÃO P/ CABO COAXIAL | D47: PÇ | E47: C | F47: =SUMIF('c'!$B:$B,$B47,'c'!$F:$F) -> 3
A48: Ferramentaria | B48: 1001941 | C48: BROCA DE WIDEA 8MM X 400MM (LONGA) | D48: UNID | E48: C | F48: =SUMIF('c'!$B:$B,$B48,'c'!$F:$F) -> 49
A49: Ferramentaria | B49: 1000089 | C49: BROCA WIDEA 6MM | D49: PÇ | E49: C | F49: =SUMIF('c'!$B:$B,$B49,'c'!$F:$F) -> 122
A50: Ferramentaria | B50: 1000170 | C50: CHAVE CANHÃO 7 MM | D50: PÇ | E50: C | F50: =SUMIF('c'!$B:$B,$B50,'c'!$F:$F) -> 11
A51: Ferramentaria | B51: 1000171 | C51: CHAVE CANHÃO 8 MM | D51: PÇ | E51: C | F51: =SUMIF('c'!$B:$B,$B51,'c'!$F:$F) -> 31
A52: Ferramentaria | B52: 1000189 | C52: CHAVE INGLESA 10MM | D52: UND | E52: C | F52: =SUMIF('c'!$B:$B,$B52,'c'!$F:$F) -> 24
A53: Ferramentaria | B53: 1000196 | C53: CHAVE PHILIPS GRANDE | D53: UND | E53: C | F53: =SUMIF('c'!$B:$B,$B53,'c'!$F:$F) -> 30
A54: Ferramentaria | B54: 1000198 | C54: CHAVE PHILIPS PEQUENA | D54: UND | E54: C | F54: =SUMIF('c'!$B:$B,$B54,'c'!$F:$F) -> 153
A55: Ferramentaria | B55: 1000262 | C55: FERRO DE CAIXA | D55: UND | E55: C | F55: =SUMIF('c'!$B:$B,$B55,'c'!$F:$F) -> 107
A56: Ferramentaria | B56: 1000470 | C56: TRENA FIBRA DE VIDRO 50M | D56: PÇ | E56: C | F56: =SUMIF('c'!$B:$B,$B56,'c'!$F:$F) -> 74
A57: Ferramentaria | B57: 1000478 | C57: VERRUMA | D57: PÇ | E57: C | F57: =SUMIF('c'!$B:$B,$B57,'c'!$F:$F) -> 30
A58: SSO | B58: 1001248 | C58: BOTA DE COURO SEM CADARÇO TAM. 36 | D58: PAR | E58: C | F58: =SUMIF('c'!$B:$B,$B58,'c'!$F:$F) -> 6
... A61: SSO | B61: 1000069 | C61: BOTA DE COURO SEM CADARÇO TAM. 39 | D61: PAR | E61: C | F61: =SUMIF('c'!$B:$B,$B61,'c'!$F:$F) -> 49
A62: SSO | B62: 1000070 | C62: BOTA DE COURO SEM CADARÇO TAM. 40 | D62: PAR | E62: A | F62: =SUMIF(a!$B:$B,$B62,a!$F:$F) -> 15
A63: SSO | B63: 1000071 | C63: BOTA DE COURO SEM CADARÇO TAM. 41 | D63: PAR | E63: A | F63: =SUMIF(a!$B:$B,$B63,a!$F:$F) -> 15
...

Sheet VITORIA
A1: CONSOLIDADO DE ESTOQUE — VITÓRIA
A2: Itens da unidade Vitória (ES). Contagem importada da planilha de origem.
A4: Categoria | B4: Código | C4: Descrição | D4: Unidade | E4: Classe (A/B/C) | F4: Quantidade
A5: FERRAMENTARIA | B5: 1000021 | C5: ALAVANCA DE AÇO 1,45MTS | D5: PÇ | E5: A | F5: 66
A6: FERRAMENTARIA | B6: 1000031 | C6: ALCOOL ISOPROPILICO 1000ML | D6: LT | E6: A | F6: 40
A7: FERRAMENTARIA | B7: 1001719 | C7: ALICATE COMPRESSÃO P/ CABO COAXIAL RG11 | D7: PÇ | E7: A | F7: 42
A8: FERRAMENTARIA | B8: 1001962 | C8: ALICATE CORTA E DESENCAPA CABO (BANANA) | D8: UNID | E8: B | F8: 12
A9: FERRAMENTARIA | B9: 1000032 | C9: ALICATE DE BICO 6 | D9: PÇ | E9: A | F9: 53
A10: FERRAMENTARIA | B10: 1000033 | C10: ALICATE DE CORTE 6 | D10: PÇ | E10: A | F10: 28
A11: FERRAMENTARIA | B11: 1001306 | C11: ALICATE DE GRIMPAR RJ11 / RJ45 | D11: UND | E11: A | F11: 30
A12: FERRAMENTARIA | B12: 1008878 | C12: ALICATE DECAPADOR COAXIAL RG6/RG7 | D12: UN | E12: B | F12: 23
A13: FERRAMENTARIA | B13: 1000037 | C13: ALICATE DECAPADOR DE FIBRA OPTICA | D13: PÇ | E13: A | F13: 56
A14: FERRAMENTARIA | B14: 1001410 | C14: ALICATE GRIMPADOR RJ-11 | D14: UND | E14: C | F14: 10
A15: FERRAMENTARIA | B15: 1001260 | C15: ALICATE P/ BOMBA DAGUA | D15: UND | E15: C | F15: 2
A16: FERRAMENTARIA | B16: 1000039 | C16: ALICATE UNIVERSAL 8 | D16: PÇ | E16: A | F16: 45
... A203: FERRAMENTARIA | B203: 1000478 | C203: VERRUMA | D203: PÇ | E203: B | F203: 24
A204: SSO | B204: 1006924 | C204: ABAFADOR RUIDO TIPO CONCHA | D204: UN | F204: 2
A205: SSO | B205: 1001850 | C205: ANEL DE ANCORAGEM 1,50M | D205: PÇ | F205: 49
A206: SSO | B206: 1006180 | C206: ANEL DE ANCORAGEM 2,00 MT | D206: UN | F206: 43
A207: SSO | B207: 1000052 | C207: BANDEROLA DE SINALIZAÇÃO | D207: UND | F207: 68
A208: SSO | B208: 1006146 | C208: BERMUDA EM BRIM COM LOGO FFA - GG | D208: UN | F208: 1
A209: SSO | B209: 1001864 | C209: BOLSA DE LONA PARA KIT LINHA DE VIDA | D209: UND | F209: 32
A210: SSO | B210: 1001249 | C210: BOTA DE COURO SEM CADARÇO TAM. 37 | D210: PAR | F210: 0
A211: SSO | B211: 1000068 | C211: BOTA DE COURO SEM CADARÇO TAM. 38 | D211: PAR | F211: 5
A212: SSO | B212: 1000069 | C212: BOTA DE COURO SEM CADARÇO TAM. 39 | D212: PAR | F212: 4
A213: SSO | B213: 1000070 | C213: BOTA DE COURO SEM CADARÇO TAM. 40 | D213: PAR | F213: 7
A214: SSO | B214: 1000071 | C214: BOTA DE COURO SEM CADARÇO TAM. 41 | D214: PAR | F214: 7
A215: SSO | B215: 1000072 | C215: BOTA DE COURO SEM CADARÇO TAM. 42 | D215: PAR | F215: 11
... A283: SSO | B283: B1002148 | C283: REAP-CALÇA CLARO FFA CINZA - P | D283: PÇ | F283: 5
A284: SSO | B284: B1001697 | C284: REAP-CALÇA CLARO FFA CINZA - G | F284: 12
A285: SSO | B285: B1001698 | C285: REAP-CALÇA CLARO FFA CINZA - GG | D285: UND | F285: 10
A286: SSO | B286: B1001699 | C286: REAP-CALÇA CLARO FFA CINZA - XG | D286: UND | F286: 4
A287: SSO | B287: B1006857 | C287: REAP-CAMISA GOLA POLO CLARO VERMELHO - EXG | D287: PÇ | F287: 4
A288: SSO | B288: B1002147 | C288: REAP-CAMISA GOLA POLO CLARO VERMELHO - EXG1 | D288: UNID | F288: 0
A289: SSO | B289: B1006853 | C289: REAP-CAMISA GOLA POLO CLARO VERMELHO - G | D289: PÇ | F289: 18
A290: SSO | B290: B1006854 | C290: REAP-CAMISA GOLA POLO CLARO VERMELHO - GG | D290: PÇ | F290: 23
A291: SSO | B291: B1006852 | C291: REAP-CAMISA GOLA POLO CLARO VERMELHO - M | D291: PÇ | F291: 10
A292: SSO | B292: B1001905 | C292: REAP-CAMISA SOCIAL SUPERVISOR CLARO IAT M | D292: UN | F292: 2
A293: SSO | B293: B1001908 | C293: REAP-CAMISA SOCIAL SUPERVISOR CLARO IAT XG | D293: UN | F293: 0
A294: SSO | B294: B1001190 | C294: REAP-CAPACETE ABA TOTAL AZESC | D294: PÇ | F294: 0
...

Sheet CONTAGEM
A1: Estado | B1: Cidade | C1: Categoria | D1: Código | E1: Descrição | F1: Unidade | G1: Quantidade | H1: Saldo em Estoque | I1: Curva ABC | J1: Diferença | K1: Acertou (exato) | L1: Valor Unitário | M1: Valor Contagem | N1: Valor Estoque
A2: RJ | B2: Rio de Janeiro | C2: FERRAMENTARIA | D2: 1000032 | E2: ALICATE DE BICO 6 | F2: PÇ | G2: 40 | H2: 102 | I2: A | J2: -62 | K2: 0 | L2: =_xlfn.XLOOKUP(D2, [1]!SINAPSE[Valor], [1]!SINAPSE[Valor], " ", 0, 1) -> #REF! | M2: 1400 | N2: 3570
A3: RJ | B3: Niterói | C3: FERRAMENTARIA | D3: 1000032 | E3: ALICATE BICO | F3: UN | G3: 5 | H3: 11 | I3: A | J3: -6 | K3: 0 | L3: 35 | M3: 175 | N3: 385
A4: RJ | B4: Lagos | C4: FERRAMENTARIA | D4: 1000032 | E4: ALICATE DE BICO 6 | F4: PÇ | G4: 4 | H4: 3 | I4: A | J4: 1 | K4: 0 | L4: 35 | M4: 140 | N4: 105
A5: MG | B5: Belo Horizonte | C5: FERRAMENTARIA | D5: 1000137 | E5: CANIVETE | F5: UN | G5: 0 | H5: 0 | I5: C | J5: 0 | K5: 1 | L5: 0 | M5: 0 | N5: 0
A6: MG | B6: Belo Horizonte | C6: FERRAMENTARIA | D6: 1002058 | E6: LENÇO UMIDECIDO COM ALCOOL PARA LIMPEZA | F6: UN | G6: 0 | H6: 0 | I6: C | J6: 0 | K6: 1 | L6: 0 | M6: 0 | N6: 0
A7: MG | B7: Belo Horizonte | C7: FERRAMENTARIA | D7: 1000032 | E7: ALICATE DE BICO 6 | F7: PÇ | G7: 29 | H7: 48 | I7: A | J7: -19 | K7: 0 | L7: 35 | M7: 1015 | N7: 1680
A8: MG | B8: Juiz de Fora | C8: FERRAMENTARIA | D8: 1000032 | E8: ALICATE DE BICO 6 | F8: PÇ | G8: 2 | H8: 6 | I8: A | J8: -4 | K8: 0 | L8: 35 | M8: 70 | N8: 210
A9: MG | B9: Uberlândia | C9: FERRAMENTARIA | D9: 1000032 | E9: ALICATE DE BICO 6 | F9: PÇ | G9: 0 | H9: 1 | I9: A | J9: -1 | K9: 0 | L9: 35 | M9: 0 | N9: 35
A10: MG | B10: Belo Horizonte | C10: FERRAMENTARIA | D10: 1001736 | E10: ORGANIZADOR GRANDE | F10: UN | G10: 0 | H10: 0 | I10: A | J10: 0 | K10: 1 | L10: 0 | M10: 0 | N10: 0
A11: RJ | B11: Petrópolis | C11: FERRAMENTARIA | D11: 1000032 | E11: ALICATE DE BICO 6 | F11: PÇ | G11: 0 | H11: 6 | I11: A | J11: -6 | K11: 0 | L11: 35 | M11: 0 | N11: 210
A12: RJ | B12: Teresópolis | C12: FERRAMENTARIA | D12: 1000032 | E12: ALICATE DE BICO 6 | F12: PÇ | G12: 0 | H12: 9 | I12: A | J12: -9 | K12: 0 | L12: 35 | M12: 0 | N12: 315
A13: MG | B13: Governador Valadares | C13: FERRAMENTARIA | D13: 1000032 | E13: ALICATE DE BICO 6 | F13: PÇ | G13: 2 | H13: 0 | I13: A | J13: 2 | K13: 0 | L13: 35 | M13: 70 | N13: 0
A14: ES | B14: Vitória | C14: FERRAMENTARIA | D14: 1000032 | E14: ALICATE DE BICO 6 | F14: PÇ | G14: 53 | H14: 41 | I14: A | J14: 12 | K14: 0 | L14: 35 | M14: 1855 | N14: 1435
... A297: RJ | B297: Niterói | C297: FERRAMENTARIA | D297: 1000348 | E297: MARTELO | F297: UN | G297: 13 | H297: 23 | I297: A | J297: -10 | K297: 0 | L297: 17 | M297: 221 | N297: 391
A298: RJ | B298: Campos dos Goytacazes | C298: FERRAMENTARIA | D298: 1000391 | E298: PASSA FIO C/ ALMA DE AÇO 20MTS | G298: 0 | H298: 0 | I298: A | J298: 0 | K298: 1 | L298: 0 | M298: 0 | N298: 0
A299: MG | B299: Belo Horizonte | C299: FERRAMENTARIA | D299: 1000348 | E299: MARTELO UNHA | F299: PÇ | G299: 0 | H299: 15 | I299: A | J299: -15 | K299: 0 | L299: 17 | M299: 0 | N299: 255
A300: RJ | B300: Campos dos Goytacazes | C300: FERRAMENTARIA | D300: 1001667 | E300: CANETA P/ LIMPEZA DE CONECTOR 2.5mm | F300: UN | G300: 0 | H300: 0 | I300: B | J300: 0 | K300: 1 | L300: 0 | M300: 0 | N300: 0
A301: RJ | B301: Campos dos Goytacazes | C301: FERRAMENTARIA | D301: 1000536 | E301: JOGO DE CHAVES ALLEN | F301: UND | G301: 4 | H301: 4 | I301: B | J301: 0 | K301: 1 | L301: 69 | M301: 276 | N301: 276
A302: ES | B302: Vitória | C302: FERRAMENTARIA | D302: 1000348 | E302: MARTELO UNHA | F302: PÇ | G302: 22 | H302: 18 | I302: A | J302: 4 | K302: 0 | L302: 17 | M302: 374 | N302: 306
A303: RJ | B303: Rio de Janeiro | C303: FERRAMENTARIA | D303: 1001941 | E303: BROCA DE WIDEA 8MM X 400MM (LONGA) | F303: UNID | G303: 49 | H303: 132 | I303: A | J303: -83 | K303: 0 | L303: 3.8 | M303: 186.2 | N303: 501.6
A304: RJ | B304: Petrópolis | C304: FERRAMENTARIA | D304: 1001941 | E304: BROCA DE WIDEA 8MM X 400MM (LONGA) | F304: UNID | G304: 0 | H304: 2 | I304: A | J304: -2 | K304: 0 | L304: 3.8 | M304: 0 | N304: 7.6
A305: RJ | B305: Teresópolis | C305: FERRAMENTARIA | D305: 1001941 | E305: BROCA DE WIDEA 8MM X 400MM (LONGA) | F305: UNID | G305: 0 | H305: 5 | I305: B | J305: -5 | K305: 0 | L305: 3.8 | M305: 0 | N305: 19
A306: RJ | B306: Lagos | C306: FERRAMENTARIA | D306: 1001476 | E306: TESTADOR DE CABO DE REDE LAN (ETHER) | F306: UN | G306: 8 | H306: 0 | I306: A | J306: 8 | K306: 0 | L306: 0 | M306: 0 | N306: 0
A307: RJ | B307: Rio de Janeiro | C307: FERRAMENTARIA | D307: 1001476 | E307: TESTADOR DE CABO DE REDE LAN (ETHER) | F307: UN | G307: 164 | H307: 0 | I307: A | J307: 164 | K307: 0 | L307: 0 | M307: 0 | N307: 0
A308: RJ | B308: Campos dos Goytacazes | C308: FERRAMENTARIA | D308: 1000089 | E308: BROCA WIDEA 6MM | F308: PÇ | G308: 7 | H308: 7 | I308: C | J308: 0 | K308: 1 | L308: 3.5 | M308: 24.5 | N308: 24.5
A309: RJ | B309: Nova Friburgo | C309: FERRAMENTARIA | D309: 1001476 | E309: TESTADOR DE CABO DE REDE LAN (ETHERNET) | F309: UN | G309: 6 | H309: 0 | I309: A | J309: 6 | K309: 0 | L309: 0 | M309: 0 | N309: 0
A310: RJ | B310: Teresópolis | C310: FERRAMENTARIA | D310: 1001476 | E310: TESTADOR DE CABO DE REDE LAN (ETHER) | F310: UN | G310: 164 | H310: 0 | I310: A | J310: 164 | K310: 0 | L310: 0 | M310: 0 | N310: 0
... A330: RJ | B330: Rio de Janeiro | C330: FERRAMENTARIA | D330: 1000171 | E330: CHAVE CANHÃO 8 MM | F330: PÇ | G330: 31 | H330: 19 | I330: A | J330: 12 | K330: 0 | L330: 15.9 | M330: 492.9 | N330: 302.1
A331: RJ | B331: Campos dos Goytacazes | C331: FERRAMENTARIA | D331: 1006121 | E331: MEDIDOR DSAM JDSU 6300 | G331: 0 | H331: 0 | I331: C | J331: 0 | K331: 1 | L331: 0 | M331: 0 | N331: 0
A332: MG | B332: Uberlândia | C332: FERRAMENTARIA | D332: 1000171 | E332: CHAVE CANHÃO 8 MM | F332: PÇ | G332: 0 | H332: 1 | I332: B | J332: -1 | K332: 0 | L332: 15.9 | M332: 0 | N332: 15.9
A333: MG | B333: Belo Horizonte | C333: FERRAMENTARIA | D333: 1000171 | E333: CHAVE CANHÃO 8 MM | F333: PÇ | G333: 0 | H333: 1 | I333: B | J333: -1 | K333: 0 | L333: 15.9 | M333: 0 | N333: 15.9
A334: RJ | B334: Rio de Janeiro | C334: FERRAMENTARIA | D334: 1000189 | E334: CHAVE INGLESA 10MM | F334: UND | G334: 24 | H334: 0 | I334: A | J334: 24 | K334: 0 | L334: 0 | M334: 0 | N334: 0
A335: RJ | B335: Rio de Janeiro | C335: FERRAMENTARIA | D335: 1000262 | E335: FERRO DE CAIXA | F335: UND | G335: 107 | H335: 0 | I335: C | J335: 107 | K335: 0 | L335: 0 | M335: 0 | N335: 0
A336: RJ | B336: Campos dos Goytacazes | C336: FERRAMENTARIA | D336: 1000392 | E336: PASSA FIO NYLON (GUIA) 20MTS | G336: 0 | H336: 0 | I336: C | J336: 0 | K336: 1 | L336: 0 | M336: 0 | N336: 0
A337: RJ | B337: Rio de Janeiro | C337: FERRAMENTARIA | D337: 1000470 | E337: TRENA FIBRA DE VIDRO 50M | F337: PÇ | G337: 74 | H337: 70 | I337: A | J337: 4 | K337: 0 | L337: 26.9 | M337: 1990.6 | N337: 1883
A338: MG | B338: Governador Valadares | C338: FERRAMENTARIA | D338: 1000039 | E338: ALICATE UNIVERSAL 8 | F338: PÇ | G338: 2 | H338: 2 | I338: A | J338: 0 | K338: 1 | L338: 35 | M338: 70 | N338: 70
A339: MG | B339: Belo Horizonte | C339: FERRAMENTARIA | D339: 1000470 | E339: TRENA FIBRA DE VIDRO 50M | F339: PÇ | G339: 0 | H339: 21 | I339: A | J339: -21 | K339: 0 | L339: 26.9 | M339: 0 | N339: 564.9
A340: MG | B340: Juiz de Fora | C340: FERRAMENTARIA | D340: 1000470 | E340: TRENA FIBRA DE VIDRO 50M | F340: PÇ | G340: 2 | H340: 1 | I340: B | J340: 1 | K340: 0 | L340: 26.9 | M340: 53.8 | N340: 26.9
A341: RJ | B341: Rio de Janeiro | C341: FERRAMENTARIA | D341: 1000478 | E341: VERRUMA | F341: PÇ | G341: 30 | H341: 0 | I341: A | J341: 30 | K341: 0 | L341: 0 | M341: 0 | N341: 0
...

Sheet LAGOS
A1: CONSOLIDADO DE ESTOQUE — LAGOS
A2: Itens da unidade Região dos Lagos (RJ).
A4: Categoria | B4: Código | C4: Descrição | D4: Unidade | E4: Classe (A/B/C) | F4: Quantidade
A5: Ferramentaria | B5: 1000032 | C5: ALICATE DE BICO 6 | D5: PÇ | E5: A | F5: 4
A6: Ferramentaria | B6: 1000033 | C6: ALICATE DE CORTE 6 | D6: PÇ | E6: A | F6: 5
A7: Ferramentaria | B7: 1001306 | C7: ALICATE DE GRIMPAR RJ11 / RJ45 | D7: UND | E7: A | F7: 3
A8: Ferramentaria | B8: 1000037 | C8: ALICATE DECAPADOR DE FIBRA OPTICA | D8: PÇ | E8: A | F8: 9
A9: Ferramentaria | B9: 1000039 | C9: ALICATE UNIVERSAL 8 | D9: PÇ | E9: A | F9: 5
A10: Ferramentaria | B10: 1001455 | C10: APLICADOR DE COLA QUENTE | D10: UN | E10: B | F10: 1
A11: FERRAMENTARIA | B11: 1001029 | C11: ARCO DE SERRA | D11: UND | E11: B | F11: 1
A12: Ferramentaria | B12: 1000048 | C12: BADISCO DIGITAL GANDOLA | D12: PÇ | E12: A | F12: 7
A13: Ferramentaria | B13: 1000049 | C13: BALDE DE LONA | D13: PÇ | E13: A | F13: 6
A14: SSO | B14: 1000071 | C14: BOTA DE COURO SEM CADARÇO TAM. 41 | D14: PAR | E14: A | F14: 4
A15: SSO | B15: 1000072 | C15: BOTA DE COURO SEM CADARÇO TAM. 42 | D15: PAR | E15: A | F15: 3
A16: SSO | B16: 1000074 | C16: BOTA DE COURO SEM CADARÇO TAM. 44 | D16: PAR | E16: B | F16: 0
A17: FERRAMENTARIA | B17: 1000814 | C17: BROCA 10MM WIDEA (CONCRETO) | E17: C | F17: 1
A18: FERRAMENTARIA | B18: 1008891 | C18: BROCA 3 PONTAS P/ MADEIRA 10MM | D18: PÇ | E18: B | F18: 1
A19: FERRAMENTARIA | B19: 1001986 | C19: BROCA 3 PONTAS P/ MADEIRA 8MM | D19: UN | E19: A | F19: 1
A20: FERRAMENTARIA | B20: 1001936 | C20: BROCA AÇO RAPIDO 3/16 | E20: C | F20: 5
A21: Ferramentaria | B21: 1001702 | C21: BROCA CHATA MADEIRA 10 MM X 150 MM | D21: UN | E21: A | F21: 2
A22: Ferramentaria | B22: 1001701 | C22: BROCA CHATA MADEIRA 8 MM X 150 MM | D22: UN | E22: B | F22: 2
A23: Ferramentaria | B23: 1001680 | C23: BROCA DE WIDEA 10MM X 400MM (LONGA) | D23: PÇ | E23: A | F23: 2
A24: FERRAMENTARIA | B24: 1006916 | C24: BROCA DE WIDEA PARA CONCRETO 6MM | D24: UN | E24: B | F24: 7
A25: Ferramentaria | B25: 1000089 | C25: BROCA WIDEA 6MM | D25: PÇ | E25: B | F25: 2
A26: FERRAMENTARIA | B26: 1001457 | C26: BROCA WIDIA 06X100MM 1/4 | E26: C | F26: 1
A27: SSO | B27: 1001697 | C27: CALÇA CLARO FFA CINZA - G | D27: UND | E27: B | F27: 1
A28: SSO | B28: 1001698 | C28: CALÇA CLARO FFA CINZA - GG | D28: UND | E28: A | F28: 1
A29: SSO | B29: 1001699 | C29: CALÇA CLARO FFA CINZA - XG | D29: UND | E29: A | F29: 0
A30: SSO | B30: 1006911 | C30: CALÇA DE BRIM AZUL MARINHO GIGA + T... | D30: UN | E30: C | F30: 3
A31: SSO | B31: 1006912 | C31: CALÇA DE BRIM AZUL MARINHO GIGA + T... | D31: UN | E31: C | F31: 9
A32: Ferramentaria | B32: 1008890 | C32: CAMERA SONDA ENDOSCOPICA- 5 M | D32: UN | E32: C | F32: 3
A33: SSO | B33: 1006909 | C33: CAMISA AZUL MARINHO GIGA + TAM EXG | D33: UN | E33: C | F33: 1
A34: SSO | B34: 1006906 | C34: CAMISA AZUL MARINHO GIGA + TAM G | D34: UN | E34: C | F34: 1
A35: SSO | B35: 1006907 | C35: CAMISA AZUL MARINHO GIGA + TAM GG | D35: UN | E35: C | F35: 7
A36: SSO | B36: 1001696 | C36: CAMISA POLO CINZA - CLARO FFA - EXG | D36: UND | E36: A | F36: 0
A37: SSO | B37: 1001693 | C37: CAMISA POLO CINZA - CLARO FFA - G | D37: UND | E37: A | F37: 2
A38: SSO | B38: 1001694 | C38: CAMISA POLO CINZA - CLARO FFA - GG | D38: UND | E38: A | F38: 0
... A40: Ferramentaria | B40: 1001289 | C40: CANETA DETECTORA DE TENSÃO 90 - 100 | D40: UND | E40: A | F40: 15
A41: FERRAMENTARIA | B41: 1001599 | C41: CANETA MARCADORA PERMANENTE | E41: C | F41: 1
A42: Ferramentaria | B42: 1001122 | C42: CANETA OPTICA - VISUAL FAULT RY V31 | D42: PÇ | E42: A | F42: 0
...

Sheet TERESOPOLIS
A1: CONSOLIDADO DE ESTOQUE — TERESÓPOLIS
A2: Itens da unidade Teresópolis (RJ).
A4: Categoria | B4: Código | C4: Descrição | D4: Unidade | E4: Classe (A/B/C) | F4: Quantidade
A5: SSO | B5: 1001850 | C5: ANEL DE ANCORAGEM 1,50M | D5: PÇ | E5: A | F5: 1
A6: SSO | B6: 1000052 | C6: BANDEROLA DE SINALIZAÇÃO | D6: UND | E6: B | F6: 5
A7: SSO | B7: 1001864 | C7: BOLSA DE LONA PARA KIT LINHA DE VIDA | D7: UND | E7: A | F7: 2
A8: Ferramentaria | B8: 1001289 | C8: CANETA DETECTORA DE TENSÃO 90 - 100 | D8: UND | E8: A | F8: 0
A9: SSO | B9: 1001302 | C9: CAPA P/ CHUVA FORRADA AMARELA | D9: PÇ | E9: A | F9: 0
A10: SSO | B10: 1001190 | C10: CAPACETE ABA TOTAL AZESC | D10: PÇ | E10: A | F10: 0
A11: SSO | B11: 1000204 | C11: CINTO SEG. PQD C/3 PONTAS E PROT. LOMBAR-APASEG | D11: PÇ | E11: A | F11: 0
A12: SSO | B12: 1002341 | C12: CINTO SEG. PQD C/3 PONTAS E PROT. L... | D12: UN | E12: C | F12: 20
A13: SSO | B13: 1000208 | C13: CONE SINALIZAÇÃO GRANDE | D13: UND | E13: A | F13: 0
A14: SSO | B14: 1001854 | C14: CORDA TRANC 12 MM LVM 20M | D14: PÇ | E14: A | F14: 0
A15: SSO | B15: 1002148 | C15: CALÇA CLARO FFA CINZA - P | D15: PÇ | E15: A | F15: 2
A16: SSO | B16: 1001697 | C16: CALÇA CLARO FFA CINZA - G | D16: UND | E16: B | F16: 4
... A40: FERRAMENTARIA | B40: 1001703 | C40: BROCA WIDEA 8 MM X 110 MM | D40: UN | E40: C | F40: 0
A41: FERRAMENTARIA | B41: 1001457 | C41: BROCA WIDIA 06X100MM 1/4 | E41: C | F41: 0
A42: FERRAMENTARIA | B42: 1000107 | C42: CADEADO 25MM | D42: PÇ | E42: B | F42: 1
A43: Ferramentaria | B43: 1000162 | C43: CHAVE BOCA / ESTRIA 11MM | D43: PÇ | E43: C | F43: 2
A44: Ferramentaria | B44: 1000838 | C44: CHAVE CANHÃO 10 | D44: UN | E44: B | F44: 50
A45: Ferramentaria | B45: 1001146 | C45: CHAVE DE ARMÁRIO TRIANGULAR | D45: PÇ | E45: A | F45: 0
A46: Ferramentaria | B46: 1000183 | C46: CHAVE DE FENDA GRANDE | D46: UND | E46: C | F46: 0
A47: Ferramentaria | B47: 1000184 | C47: CHAVE DE FENDA MEDIA | D47: UND | E47: C | F47: 0
A48: Ferramentaria | B48: 1000185 | C48: CHAVE DE FENDA PEQUENA | D48: UND | E48: A | F48: 0
A49: Ferramentaria | B49: 1006116 | C49: CHAVE GTP TRAVA E DESTRAVA CURTA | D49: PÇ | E49: A | F49: 0
A50: Ferramentaria | B50: 1001707 | C50: CHAVE MINI TRAP ST1 P/ CONECTOR RG | D50: UN | E50: A | F50: 26
A51: Ferramentaria | B51: 1000195 | C51: CHAVE P/ CAIXA SUBTERRANEA | D51: PÇ | E51: C | F51: 101
A52: Ferramentaria | B52: 1000196 | C52: CHAVE PHILIPS GRANDE | D52: UND | E52: C | F52: 0
A53: Ferramentaria | B53: 1000197 | C53: CHAVE PHILIPS MEDIA | D53: UND | E53: C | F53: 0
... A58: FERRAMENTARIA | B58: 1000481 | C58: DECAPADOR DE CABOS | D58: UND | E58: B | F58: 6
A59: FERRAMENTARIA | B59: 1006821 | C59: DESUMIDIFICADOR DE PAPEL 600 FOLHAS A4 BIVOLT | F59: 1
A60: Ferramentaria | B60: 1001488 | C60: ESCADA 5 DEGRAUS DOMESTICA | D60: UN | E60: A | F60: 0
A61: FERRAMENTARIA | B61: 1000254 | C61: ESTILETE | D61: PÇ | E61: A | F61: 2
A62: Ferramentaria | B62: 1000258 | C62: EXTENSAO ELET. 10MTS | D62: PÇ | E62: B | F62: 0
A63: Ferramentaria | B63: 1001264 | C63: FERRO DE ABRIR CAIXA TIPO T | D63: UND | E63: A | F63: 0
A64: Ferramentaria | B64: 1000262 | C64: FERRO DE CAIXA | D64: UND | E64: C | F64: 0
A65: Ferramentaria | B65: 1000284 | C65: FURADEIRA - IMPACTO | D65: UND | E65: A | F65: 23
A66: Ferramentaria | B66: 1001940 | C66: FURADEIRA SKIL MODELO 6662 550W 127V | D66: UND | E66: C | F66: 0
A67: Ferramentaria | B67: 1001705 | C67: JOGO CHAVE ALLEN C/ 25 PÇS | D67: UN | E67: A | F67: 3
A68: Ferramentaria | B68: 1001552 | C68: KIT DE CHAVE RELOJOEIRO C/ 6 PÇS | D68: CJ | E68: C | F68: 6
...

Sheet PETROPOLIS
A1: CONSOLIDADO DE ESTOQUE — PETRÓPOLIS
A2: Itens da unidade Petrópolis (RJ).
A4: Categoria | B4: Código | C4: Descrição | D4: Unidade | E4: Classe (A/B/C) | F4: Quantidade
A5: FERRAMENTARIA | B5: 1001663 | C5: ADAPTADOR P/ CONECTOR SC-APC (POWER METER) | D5: UN | E5: B | F5: 1
A6: FERRAMENTARIA | B6: 1000031 | C6: ALCOOL ISOPROPILICO 1000ML | D6: LT | E6: A | F6: 0
A7: Ferramentaria | B7: 1001719 | C7: ALICATE COMPRESSÃO P/ CABO COAXIAL | D7: PÇ | E7: A | F7: 3
A8: Ferramentaria | B8: 1000032 | C8: ALICATE DE BICO 6 | D8: PÇ | E8: A | F8: 0
A9: Ferramentaria | B9: 1000033 | C9: ALICATE DE CORTE 6 | D9: PÇ | E9: A | F9: 11
A10: Ferramentaria | B10: 1001306 | C10: ALICATE DE GRIMPAR RJ11 / RJ45 | D10: UND | E10: A | F10: 0
A11: Ferramentaria | B11: 1000036 | C11: ALICATE DE PRESSÃO RG6 | D11: PÇ | E11: B | F11: 50
A12: Ferramentaria | B12: 1000037 | C12: ALICATE DECAPADOR DE FIBRA OPTICA | D12: PÇ | E12: A | F12: 0
A13: Ferramentaria | B13: 1000039 | C13: ALICATE UNIVERSAL 8 | D13: PÇ | E13: A | F13: 0
A14: Ferramentaria | B14: 1001455 | C14: APLICADOR DE COLA QUENTE | D14: UN | E14: B | F14: 103
A15: Ferramentaria | B15: 1000048 | C15: BADISCO DIGITAL GANDOLA | D15: PÇ | E15: A | F15: 198
A16: Ferramentaria | B16: 1000049 | C16: BALDE DE LONA | D16: PÇ | E16: A | F16: 0
... A27: FERRAMENTARIA | B27: 1001703 | C27: BROCA WIDEA 8 MM X 110 MM | D27: UN | E27: C | F27: 0
A28: FERRAMENTARIA | B28: 1001457 | C28: BROCA WIDIA 06X100MM 1/4 | E28: C | F28: 0
A29: Ferramentaria | B29: 1006819 | C29: CAIXA VAZADA 50L PRETA | D29: UN | E29: B | F29: 1
A30: Ferramentaria | B30: 1008890 | C30: CAMERA SONDA ENDOSCOPICA- 5 M | D30: UN | E30: C | F30: 0
A31: Ferramentaria | B31: 1001667 | C31: CANETA P/ LIMPEZA DE CONECTOR 2.5mm | D31: UN | E31: B | F31: 116
A32: Ferramentaria | B32: 1001122 | C32: CANETA OPTICA - VISUAL FAULT RY V31 | D32: PÇ | E32: A | F32: 9
A33: Ferramentaria | B33: 1000162 | C33: CHAVE BOCA / ESTRIA 11MM | D33: PÇ | E33: C | F33: 0
A34: Ferramentaria | B34: 1001146 | C34: CHAVE DE ARMÁRIO TRIANGULAR | D34: PÇ | E34: A | F34: 59
A35: Ferramentaria | B35: 1000183 | C35: CHAVE DE FENDA GRANDE | D35: UND | E35: C | F35: 64
A36: Ferramentaria | B36: 1000184 | C36: CHAVE DE FENDA MEDIA | D36: UND | E36: C | F36: 0
A37: Ferramentaria | B37: 1000185 | C37: CHAVE DE FENDA PEQUENA | D37: UND | E37: A | F37: 0
A38: Ferramentaria | B38: 1006116 | C38: CHAVE GTP TRAVA E DESTRAVA CURTA | D38: PÇ | E38: A | F38: 0
A39: Ferramentaria | B39: 1001707 | C39: CHAVE MINI TRAP ST1 P/ CONECTOR RG | D39: UN | E39: A | F39: 0
A40: Ferramentaria | B40: 1000195 | C40: CHAVE P/ CAIXA SUBTERRANEA | D40: PÇ | E40: C | F40: 0
... A74: FERRAMENTARIA | B74: 1001461 | C74: TUBO DE COLA QUENTE | D74: UN | E74: B | F74: 0

Sheet CAMPOS DOS GOYTACAZES
A1: CONSOLIDADO DE ESTOQUE — CAMPOS DOS GOYTACAZES
A2: Itens da unidade Campos dos Goytacazes. Código e classe (A/B/C) buscados na aba 'de para abc' pelo nome do item.
A4: Categoria | B4: Código | C4: Descrição | D4: Unidade | E4: Classe (A/B/C) | F4: Quantidade
A5: =IFERROR(INDEX('de para abc'!$D:$D,MATCH($C5,'de para abc'!$B:$B,0)),"N/D") -> SSO | B5: 1000052 | C5: BANDEROLA DE SINALIZAÇÃO | D5: UND | E5: C | F5: 3
A6: =IFERROR(INDEX('de para abc'!$D:$D,MATCH($C6,'de para abc'!$B:$B,0)),"N/D") -> FERRAMENTARIA | B6: 1002052 | C6: BOBINA PICOTADA 50X70 | E6: =IFERROR(T(INDEX('de para abc'!$C:$C,MATCH($C6,'de para abc'!$B:$B,0))),"N/D") | F6: 7
A7: =IFERROR(INDEX('de para abc'!$D:$D,MATCH($C7,'de para abc'!$B:$B,0)),"N/D") -> FERRAMENTARIA | B7: 1000065 | C7: BOLSA DE LONA | D7: PÇ | E7: A | F7: 5
A8: =IFERROR(INDEX('de para abc'!$D:$D,MATCH($C8,'de para abc'!$B:$B,0)),"N/D") -> FERRAMENTARIA | B8: 1000814 | C8: BROCA 10MM WIDEA (CONCRETO) | E8: C | F8: 3
A9: =IFERROR(INDEX('de para abc'!$D:$D,MATCH($C9,'de para abc'!$B:$B,0)),"N/D") -> FERRAMENTARIA | B9: 1008891 | C9: BROCA 3 PONTAS P/ MADEIRA 10MM | D9: PÇ | E9: B | F9: 6
A10: Ferramentaria | B10: 1001712 | C10: BROCA CHATA MADEIRA 6MM X 150MM | D10: UN | E10: B | F10: 7
A11: Ferramentaria | B11: 1001702 | C11: BROCA CHATA MADEIRA 10 MM X 150 MM | D11: UN | E11: A | F11: 21
A12: Ferramentaria | B12: 1001701 | C12: BROCA CHATA MADEIRA 8 MM X 150 MM | D12: UN | E12: A | F12: 15
A13: Ferramentaria | B13: 1001680 | C13: BROCA DE WIDEA 10MM X 400MM (LONGA) | D13: PÇ | E13: A | F13: 15
A14: =IFERROR(INDEX('de para abc'!$D:$D,MATCH($C14,'de para abc'!$B:$B,0)),"N/D") -> FERRAMENTARIA | B14: 1001941 | C14: BROCA DE WIDEA 8MM X 400MM (LONGA) | D14: UNID | E14: C | F14: 5
A15: FERRAMENTARIA | B15: 1001719 | C15: ALICATE COMPRESSÃO P/ CABO COAXIAL | D15: PÇ | E15: C | F15: 6
A16: =IFERROR(INDEX('de para abc'!$D:$D,MATCH($C16,'de para abc'!$B:$B,0)),"N/D") -> FERRAMENTARIA | B16: 1000049 | C16: BALDE DE LONA | D16: PÇ | E16: B | F16: 11
A17: =IFERROR(INDEX('de para abc'!$D:$D,MATCH($C17,'de para abc'!$B:$B,0)),"N/D") -> FERRAMENTARIA | B17: 1000048 | C17: BADISCO DIGITAL GANDOLA | D17: PÇ | E17: A | F17: 14
A18: =IFERROR(INDEX('de para abc'!$D:$D,MATCH($C18,'de para abc'!$B:$B,0)),"N/D") -> FERRAMENTARIA | B18: 1001455 | C18: APLICADOR DE COLA QUENTE | D18: UN | E18: A | F18: 8
A19: =IFERROR(INDEX('de para abc'!$D:$D,MATCH($C19,'de para abc'!$B:$B,0)),"N/D") -> FERRAMENTARIA | B19: 1000039 | C19: ALICATE UNIVERSAL 8 | D19: PÇ | E19: A | F19: 10
A20: Ferramentaria | B20: 1000037 | C20: ALICATE DECAPADOR DE FIBRA OPTICA | D20: PÇ | E20: B | F20: 13
A21: =IFERROR(INDEX('de para abc'!$D:$D,MATCH($C21,'de para abc'!$B:$B,0)),"N/D") -> FERRAMENTARIA | B21: 1000036 | C21: ALICATE DE PRESSÃO RG6 | D21: PÇ | E21: A | F21: 5
A22: Ferramentaria | B22: 1001306 | C22: ALICATE DE GRIMPAR RJ11 / RJ45 | D22: UND | E22: A | F22: 12
A23: =IFERROR(INDEX('de para abc'!$D:$D,MATCH($C23,'de para abc'!$B:$B,0)),"N/D") -> FERRAMENTARIA | B23: 1000033 | C23: ALICATE DE CORTE 6 | D23: PÇ | E23: A | F23: 10
A24: =IFERROR(INDEX('de para abc'!$D:$D,MATCH($C24,'de para abc'!$B:$B,0)),"N/D") -> FERRAMENTARIA | B24: 1000032 | C24: ALICATE DE BICO 6 | D24: PÇ | E24: A | F24: 9
A25: =IFERROR(INDEX('de para abc'!$D:$D,MATCH($C25,'de para abc'!$B:$B,0)),"N/D") -> FERRAMENTARIA | B25: 1001663 | C25: ADAPTADOR P/ CONECTOR SC-APC (POWER METER) | D25: UN | E25: B | F25: 1
A26: =IFERROR(INDEX('de para abc'!$D:$D,MATCH($C26,'de para abc'!$B:$B,0)),"N/D") -> FERRAMENTARIA | B26: 1000183 | C26: CHAVE DE FENDA GRANDE | D26: UND | E26: B | F26: 24
A27: Ferramentaria | B27: 1000184 | C27: CHAVE DE FENDA MEDIA | D27: UND | E27: A | F27: 9
A28: =IFERROR(INDEX('de para abc'!$D:$D,MATCH($C28,'de para abc'!$B:$B,0)),"N/D") -> FERRAMENTARIA | B28: 1000185 | C28: CHAVE DE FENDA PEQUENA | D28: UND | E28: B | F28: 16
A29: =IFERROR(INDEX('de para abc'!$D:$D,MATCH($C29,'de para abc'!$B:$B,0)),"N/D") -> FERRAMENTARIA | B29: 1001263 | C29: CHAVE DE TESTE DIGITAL COM DISPLAY | D29: UND | E29: B | F29: 1
A30: =IFERROR(INDEX('de para abc'!$D:$D,MATCH($C30,'de para abc'!$B:$B,0)),"N/D") -> FERRAMENTARIA | B30: 1006116 | C30: CHAVE GTP TRAVA E DESTRAVA CURTA | D30: PÇ | E30: A | F30: 13
A31: FERRAMENTARIA | B31: 1001707 | C31: CHAVE MINI TRAP ST1 P/ CONECTOR RG | D31: UN | E31: A | F31: 12
A32: Ferramentaria | B32: 1000195 | C32: CHAVE P/ CAIXA SUBTERRANEA | D32: PÇ | E32: A | F32: 12
A33: =IFERROR(INDEX('de para abc'!$D:$D,MATCH($C33,'de para abc'!$B:$B,0)),"N/D") -> FERRAMENTARIA | B33: 1000196 | C33: CHAVE PHILIPS GRANDE | D33: UND | E33: C | F33: 26
A34: Ferramentaria | B34: 1000197 | C34: CHAVE PHILIPS MEDIA | D34: UND | E34: B | F34: 21
A35: =IFERROR(INDEX('de para abc'!$D:$D,MATCH($C35,'de para abc'!$B:$B,0)),"N/D") -> FERRAMENTARIA | B35: 1000198 | C35: CHAVE PHILIPS PEQUENA | D35: UND | E35: C | F35: 13
A36: FERRAMENTARIA | B36: 1001704 | C36: BROCA WIDEA 10 MM X 150 MM | D36: UN | E36: A | F36: 2
A37: =IFERROR(INDEX('de para abc'!$D:$D,MATCH($C37,'de para abc'!$B:$B,0)),"N/D") -> FERRAMENTARIA | B37: 1000089 | C37: BROCA WIDEA 6MM | D37: PÇ | E37: C | F37: 7
A38: FERRAMENTARIA | B38: 1001703 | C38: BROCA WIDEA 8 MM X 110 MM | D38: UN | E38: C | F38: 2
A39: =IFERROR(INDEX('de para abc'!$D:$D,MATCH($C39,'de para abc'!$B:$B,0)),"N/D") -> FERRAMENTARIA | B39: 1006819 | C39: CAIXA VAZADA 50L PRETA | D39: UN | E39: C | F39: 24
A40: Ferramentaria | B40: 1008890 | C40: CAMERA SONDA ENDOSCOPICA- 5 M | D40: UN | E40: A | F40: 2
A41: Ferramentaria | B41: 1001667 | C41: CANETA P/ LIMPEZA DE CONECTOR 2.5mm | D41: UN | E41: A | F41: 0
...

Sheet SAO PAULO
A1: CONSOLIDADO DE ESTOQUE — SÃO PAULO
A2: Itens da unidade São Paulo (SP).
A4: Categoria | B4: Código | C4: Descrição | D4: Unidade | E4: Classe (A/B/C) | F4: Quantidade
A5: SSO | B5: 1000014 | C5: ABRAÇADEIRA NYLON (FITA HELLERMAN) - MÉDIA | D5: UND | E5: B | F5: 46
A6: SSO | B6: 1001850 | C6: ANEL DE ANCORAGEM 1,50M | D6: PÇ | E6: A | F6: 85
A7: SSO | B7: 1006180 | C7: ANEL DE ANCORAGEM 2,00 MT | D7: UN | E7: A | F7: 80
A8: SSO | B8: 1000052 | C8: BANDEROLA DE SINALIZAÇÃO | D8: UND | E8: C | F8: 52
A9: SSO | B9: 1001864 | C9: BOLSA DE LONA PARA KIT LINHA DE VIDA | D9: UND | E9: A | F9: 55
A10: SSO | B10: 1001522 | C10: BOTA BORRACHA PVC 39 | D10: un | E10: C | F10: 0
A11: SSO | B11: 1001524 | C11: BOTA BORRACHA PVC 41 | D11: un | E11: C | F11: 0
A12: SSO | B12: 1001525 | C12: BOTA BORRACHA PVC 42 | D12: un | E12: C | F12: 0
A13: SSO | B13: 1001526 | C13: BOTA BORRACHA PVC 43 | D13: un | E13: C | F13: 0
A14: SSO | B14: 1001527 | C14: BOTA BORRACHA PVC 44 | D14: un | E14: C | F14: 0
A15: SSO | B15: 1001249 | C15: BOTA DE COURO SEM CADARÇO TAM. 37 | D15: PAR | E15: C | F15: 19
A16: SSO | B16: 1000068 | C16: BOTA DE COURO SEM CADARÇO TAM. 38 | D16: PAR | E16: C | F16: 16
... A27: SSO | B27: 1002180 | C27: CABO USB UNIVERSAL | D27: PÇ | E27: C | F27: 1
A28: SSO | B28: 1002276 | C28: CALÇA CINZA VIVO C/ FAIXA REFLETIVA - P | E28: C | F28: 2
A29: SSO | B29: 1002273 | C29: CALÇA CINZA VIVO C/ FAIXA REFLETIVA - G | D29: UN | E29: B | F29: 34
A30: SSO | B30: 1002274 | C30: CALÇA CINZA VIVO C/ FAIXA REFLETIVA - GG | D30: UN | E30: C | F30: 58
A31: SSO | B31: 1002303 | C31: CALÇA CINZA VIVO C/ FAIXA REFLETIVA - XXG | E31: C | F31: 9
A32: SSO | B32: 1002352 | C32: CALÇA CINZA VIVO C/ FAIXA REFLETIVA - EXG | D32: UN | E32: C | F32: 25
A33: SSO | B33: 1002275 | C33: CALÇA CINZA VIVO C/ FAIXA REFLETIVA - M | D33: UN | E33: C | F33: 1
A34: SSO | B34: 1002302 | C34: CALÇA CINZA VIVO C/ FAIXA REFLETIVA - XG | D34: UN | E34: C | F34: 54
A35: SSO | B35: 1002140 | C35: CALÇA JEANS C/ FAIXA REFLETIVA - 48 | D35: UNID | E35: C | F35: 0
A36: SSO | B36: 1001992 | C36: CALÇA JEANS C/ FAIXA REFLETIVA IHS - 38 | D36: UN | E36: B | F36: 7
A37: SSO | B37: 1001993 | C37: CALÇA JEANS C/ FAIXA REFLETIVA IHS - 40 | D37: UN | E37: B | F37: 59
A38: SSO | B38: 1001994 | C38: CALÇA JEANS C/ FAIXA REFLETIVA IHS - 42 | D38: UN | E38: A | F38: 44
A39: SSO | B39: 1001995 | C39: CALÇA JEANS C/ FAIXA REFLETIVA IHS – 44 | D39: UN | E39: A | F39: 34
A40: SSO | B40: 1001996 | C40: CALÇA JEANS C/ FAIXA REFLETIVA IHS – 46 | D40: UN | E40: A | F40: 30
A41: SSO | B41: 1001997 | C41: CALÇA JEANS C/ FAIXA REFLETIVA IHS – 48 | D41: UN | E41: A | F41: 24
A42: SSO | B42: 1001998 | C42: CALÇA JEANS C/ FAIXA REFLETIVA IHS - 50 | D42: UN | E42: B | F42: 34
A43: SSO | B43: 1001999 | C43: CALÇA JEANS C/ FAIXA REFLETIVA IHS – 52 | D43: UN | E43: B | F43: 36
... A46: SSO | B46: 1002325 | C46: CALÇA JEANS C/ FAIXA REFLETIVA IHS G3 | D46: UN | E46: C | F46: 0
A47: SSO | B47: 1002319 | C47: CALÇA JEANS COM FAIXA REFLATIVA IHS - G3 | E47: C | F47: 10
A48: SSO | B48: 1002318 | C48: CALÇA JEANS COM FAIXA REFLETIVA IHS - GG | D48: PÇ | E48: C | F48: 5
A49: SSO | B49: 1002317 | C49: CAMISA ROXA VIVO - EG | E49: C | F49: 24
A50: SSO | B50: 1002337 | C50: CAMISA ROXA VIVO - EXG | D50: UN | E50: C | F50: 47
A51: SSO | B51: 1002338 | C51: CAMISA ROXA VIVO - EXG1 | E51: C | F51: 36
A52: SSO | B52: 1002279 | C52: CAMISA ROXA VIVO - G | D52: UN | E52: B | F52: 44
A53: SSO | B53: 1002335 | C53: CAMISA ROXA VIVO - G1 | E53: C | F53: 24
...

Sheet NOVA FRIBURGO
A1: CONSOLIDADO DE ESTOQUE — NOVA FRIBURGO
A2: Itens da unidade Nova Friburgo. Código e classe (A/B/C) buscados na aba 'de para abc' pelo nome do item.
A4: Categoria | B4: Código | C4: Descrição | D4: Unidade | E4: Classe (A/B/C) | F4: Quantidade
A5: Ferramentaria | B5: {=IFERROR(INDEX('de para abc'!$A:$A,MATCH($C5,'de para abc'!$B:$B,0)),"N/D")} -> 1001663 | C5: ADAPTADOR P/ CONECTOR SC-APC (POWER METER) | D5: UN | E5: {=IFERROR(INDEX('de para abc'!$C:$C,MATCH($C5,'de para abc'!$B:$B,0)),"N/D")} -> B | F5: 11
A6: Ferramentaria | B6: {=IFERROR(INDEX('de para abc'!$A:$A,MATCH($C6,'de para abc'!$B:$B,0)),"N/D")} -> 1000032 | C6: ALICATE DE BICO 6 | D6: PÇ | E6: {=IFERROR(INDEX('de para abc'!$C:$C,MATCH($C6,'de para abc'!$B:$B,0)),"N/D")} -> A | F6: 9
A7: Ferramentaria | B7: {=IFERROR(INDEX('de para abc'!$A:$A,MATCH($C7,'de para abc'!$B:$B,0)),"N/D")} -> 1000033 | C7: ALICATE DE CORTE 6 | D7: PÇ | E7: {=IFERROR(INDEX('de para abc'!$C:$C,MATCH($C7,'de para abc'!$B:$B,0)),"N/D")} -> A | F7: 2
A8: Ferramentaria | B8: {=IFERROR(INDEX('de para abc'!$A:$A,MATCH($C8,'de para abc'!$B:$B,0)),"N/D")} -> 1001306 | C8: ALICATE DE GRIMPAR RJ11 / RJ45 | D8: UND | E8: {=IFERROR(INDEX('de para abc'!$C:$C,MATCH($C8,'de para abc'!$B:$B,0)),"N/D")} -> A | F8: 4
A9: Ferramentaria | B9: {=IFERROR(INDEX('de para abc'!$A:$A,MATCH($C9,'de para abc'!$B:$B,0)),"N/D")} -> 1000037 | C9: ALICATE DECAPADOR DE FIBRA OPTICA | D9: PÇ | E9: {=IFERROR(INDEX('de para abc'!$C:$C,MATCH($C9,'de para abc'!$B:$B,0)),"N/D")} -> A | F9: 4
A10: Ferramentaria | B10: {=IFERROR(INDEX('de para abc'!$A:$A,MATCH($C10,'de para abc'!$B:$B,0)),"N/D")} -> 1000039 | C10: ALICATE UNIVERSAL 8 | D10: PÇ | E10: {=IFERROR(INDEX('de para abc'!$C:$C,MATCH($C10,'de para abc'!$B:$B,0)),"N/D")} -> A | F10: 11
A11: Ferramentaria | B11: {=IFERROR(INDEX('de para abc'!$A:$A,MATCH($C11,'de para abc'!$B:$B,0)),"N/D")} -> 1001455 | C11: APLICADOR DE COLA QUENTE | D11: UN | E11: {=IFERROR(INDEX('de para abc'!$C:$C,MATCH($C11,'de para abc'!$B:$B,0)),"N/D")} -> A | F11: 6
A12: Ferramentaria | B12: {=IFERROR(INDEX('de para abc'!$A:$A,MATCH($C12,'de para abc'!$B:$B,0)),"N/D")} -> 1000048 | C12: BADISCO DIGITAL GANDOLA | D12: PÇ | E12: {=IFERROR(INDEX('de para abc'!$C:$C,MATCH($C12,'de para abc'!$B:$B,0)),"N/D")} -> A | F12: 5
A13: Ferramentaria | B13: {=IFERROR(INDEX('de para abc'!$A:$A,MATCH($C13,'de para abc'!$B:$B,0)),"N/D")} -> 1000049 | C13: BALDE DE LONA | D13: PÇ | E13: {=IFERROR(INDEX('de para abc'!$C:$C,MATCH($C13,'de para abc'!$B:$B,0)),"N/D")} -> A | F13: 6
A14: Ferramentaria | B14: {=IFERROR(INDEX('de para abc'!$A:$A,MATCH($C14,'de para abc'!$B:$B,0)),"N/D")} -> 1000060 | C14: BATERIA 9 V | D14: PÇ | E14: {=IFERROR(INDEX('de para abc'!$C:$C,MATCH($C14,'de para abc'!$B:$B,0)),"N/D")} -> C | F14: 12
A15: Ferramentaria | B15: {=IFERROR(INDEX('de para abc'!$A:$A,MATCH($C15,'de para abc'!$B:$B,0)),"N/D")} -> 1000065 | C15: BOLSA DE LONA | D15: PÇ | E15: {=IFERROR(INDEX('de para abc'!$C:$C,MATCH($C15,'de para abc'!$B:$B,0)),"N/D")} -> A | F15: 10
A16: Ferramentaria | B16: {=IFERROR(INDEX('de para abc'!$A:$A,MATCH($C16,'de para abc'!$B:$B,0)),"N/D")} -> 1000082 | C16: BROCA 5/16 X 8 WIDIA | D16: UND | E16: C | F16: 1
A17: Ferramentaria | B17: {=IFERROR(INDEX('de para abc'!$A:$A,MATCH($C17,'de para abc'!$B:$B,0)),"N/D")} -> 1001712 | C17: BROCA CHATA MADEIRA 6MM X 150MM | D17: UN | E17: {=IFERROR(INDEX('de para abc'!$C:$C,MATCH($C17,'de para abc'!$B:$B,0)),"N/D")} -> B | F17: 2
A18: Ferramentaria | B18: {=IFERROR(INDEX('de para abc'!$A:$A,MATCH($C18,'de para abc'!$B:$B,0)),"N/D")} -> 1001702 | C18: BROCA CHATA MADEIRA 10 MM X 150 MM | D18: UN | E18: {=IFERROR(INDEX('de para abc'!$C:$C,MATCH($C18,'de para abc'!$B:$B,0)),"N/D")} -> B | F18: 7
A19: Ferramentaria | B19: {=IFERROR(INDEX('de para abc'!$A:$A,MATCH($C19,'de para abc'!$B:$B,0)),"N/D")} -> 1001701 | C19: BROCA CHATA MADEIRA 8 MM X 150 MM | D19: UN | E19: {=IFERROR(INDEX('de para abc'!$C:$C,MATCH($C19,'de para abc'!$B:$B,0)),"N/D")} -> B | F19: 9
A20: Ferramentaria | B20: {=IFERROR(INDEX('de para abc'!$A:$A,MATCH($C20,'de para abc'!$B:$B,0)),"N/D")} -> 1001305 | C20: BROCA DE VIDIA 12 MM X 30 CM | D20: UND | E20: C | F20: 1
A21: Ferramentaria | B21: {=IFERROR(INDEX('de para abc'!$A:$A,MATCH($C21,'de para abc'!$B:$B,0)),"N/D")} -> 1001680 | C21: BROCA DE WIDEA 10MM X 400MM ( LONGA) | D21: PÇ | E21: {=IFERROR(INDEX('de para abc'!$C:$C,MATCH($C21,'de para abc'!$B:$B,0)),"N/D")} -> A | F21: 13
A22: Ferramentaria | B22: {=IFERROR(INDEX('de para abc'!$A:$A,MATCH($C22,'de para abc'!$B:$B,0)),"N/D")} -> 1001941 | C22: BROCA DE WIDEA 8MM X 400MM (LONGA) | D22: UNID | E22: {=IFERROR(INDEX('de para abc'!$C:$C,MATCH($C22,'de para abc'!$B:$B,0)),"N/D")} -> A | F22: 2
A23: Ferramentaria | B23: {=IFERROR(INDEX('de para abc'!$A:$A,MATCH($C23,'de para abc'!$B:$B,0)),"N/D")} -> 1001704 | C23: BROCA WIDEA 10 MM X 150 MM | D23: UN | E23: {=IFERROR(INDEX('de para abc'!$C:$C,MATCH($C23,'de para abc'!$B:$B,0)),"N/D")} -> C | F23: 2
A24: Ferramentaria | B24: {=IFERROR(INDEX('de para abc'!$A:$A,MATCH($C24,'de para abc'!$B:$B,0)),"N/D")} -> 1001703 | C24: BROCA WIDEA 8 MM X 110 MM | D24: UN | E24: {=IFERROR(INDEX('de para abc'!$C:$C,MATCH($C24,'de para abc'!$B:$B,0)),"N/D")} -> C | F24: 4
A25: Ferramentaria | B25: {=IFERROR(INDEX('de para abc'!$A:$A,MATCH($C25,'de para abc'!$B:$B,0)),"N/D")} -> 1006819 | C25: CAIXA VAZADA 50L PRETA | D25: UN | E25: {=IFERROR(INDEX('de para abc'!$C:$C,MATCH($C25,'de para abc'!$B:$B,0)),"N/D")} -> C | F25: 2
A26: Ferramentaria | B26: {=IFERROR(INDEX('de para abc'!$A:$A,MATCH($C26,'de para abc'!$B:$B,0)),"N/D")} -> 1008890 | C26: CAMERA SONDA ENDOSCOPICA- 5 M | D26: UN | E26: {=IFERROR(INDEX('de para abc'!$C:$C,MATCH($C26,'de para abc'!$B:$B,0)),"N/D")} -> C | F26: 1
A27: Ferramentaria | B27: {=IFERROR(INDEX('de para abc'!$A:$A,MATCH($C27,'de para abc'!$B:$B,0)),"N/D")} -> 1001667 | C27: CANETA P/ LIMPEZA DE CONECTOR 2.5mm | D27: UN | E27: {=IFERROR(INDEX('de para abc'!$C:$C,MATCH($C27,'de para abc'!$B:$B,0)),"N/D")} -> A | F27: 13
A28: Ferramentaria | B28: {=IFERROR(INDEX('de para abc'!$A:$A,MATCH($C28,'de para abc'!$B:$B,0)),"N/D")} -> 1001122 | C28: CANETA OPTICA - VISUAL FAULT RY V3105 | D28: PÇ | E28: {=IFERROR(INDEX('de para abc'!$C:$C,MATCH($C28,'de para abc'!$B:$B,0)),"N/D")} -> A | F28: 2
A29: Ferramentaria | B29: {=IFERROR(INDEX('de para abc'!$A:$A,MATCH($C29,'de para abc'!$B:$B,0)),"N/D")} -> 1000162 | C29: CHAVE BOCA / ESTRIA 11MM | D29: PÇ | E29: {=IFERROR(INDEX('de para abc'!$C:$C,MATCH($C29,'de para abc'!$B:$B,0)),"N/D")} -> C | F29: 1
A30: Ferramentaria | B30: {=IFERROR(INDEX('de para abc'!$A:$A,MATCH($C30,'de para abc'!$B:$B,0)),"N/D")} -> 1001146 | C30: CHAVE DE ARMÁRIO TRIANGULAR | D30: PÇ | E30: {=IFERROR(INDEX('de para abc'!$C:$C,MATCH($C30,'de para abc'!$B:$B,0)),"N/D")} -> B | F30: 3
A31: Ferramentaria | B31: {=IFERROR(INDEX('de para abc'!$A:$A,MATCH($C31,'de para abc'!$B:$B,0)),"N/D")} -> 1000183 | C31: CHAVE DE FENDA GRANDE | D31: UND | E31: {=IFERROR(INDEX('de para abc'!$C:$C,MATCH($C31,'de para abc'!$B:$B,0)),"N/D")} -> A | F31: 3
A32: Ferramentaria | B32: {=IFERROR(INDEX('de para abc'!$A:$A,MATCH($C32,'de para abc'!$B:$B,0)),"N/D")} -> 1000184 | C32: CHAVE DE FENDA MEDIA | D32: UND | E32: {=IFERROR(INDEX('de para abc'!$C:$C,MATCH($C32,'de para abc'!$B:$B,0)),"N/D")} -> A | F32: 30
... A72: Ferramentaria | B72: {=IFERROR(INDEX('de para abc'!$A:$A,MATCH($C72,'de para abc'!$B:$B,0)),"N/D")} -> 1001461 | C72: TUBO DE COLA QUENTE | D72: UN | E72: {=IFERROR(INDEX('de para abc'!$C:$C,MATCH($C72,'de para abc'!$B:$B,0)),"N/D")} -> C | F72: 13
A73: SSO | B73: {=IFERROR(INDEX('de para abc'!$A:$A,MATCH($C73,'de para abc'!$B:$B,0)),"N/D")} -> 1001850 | C73: ANEL DE ANCORAGEM 1,50M | D73: PÇ | E73: C | F73: 4
A74: SSO | B74: {=IFERROR(INDEX('de para abc'!$A:$A,MATCH($C74,'de para abc'!$B:$B,0)),"N/D")} -> 1006180 | C74: ANEL DE ANCORAGEM 2,00 MT | D74: UN | E74: C | F74: 1
A75: SSO | B75: {=IFERROR(INDEX('de para abc'!$A:$A,MATCH($C75,'de para abc'!$B:$B,0)),"N/D")} -> 1000052 | C75: BANDEROLA DE SINALIZAÇÃO | D75: UND | E75: {=IFERROR(INDEX('de para abc'!$C:$C,MATCH($C75,'de para abc'!$B:$B,0)),"N/D")} -> A | F75: 1
A76: SSO | B76: 1001864 | C76: BOLSA DE LONA PARA KIT LINHA DE VI... | D76: UND | E76: C | F76: 4
A77: SSO | B77: {=IFERROR(INDEX('de para abc'!$A:$A,MATCH($C77,'de para abc'!$B:$B,0)),"N/D")} -> 1001249 | C77: BOTA DE COURO SEM CADARÇO TAM. 37 | D77: PAR | E77: C | F77: 1
A78: SSO | B78: {=IFERROR(INDEX('de para abc'!$A:$A,MATCH($C78,'de para abc'!$B:$B,0)),"N/D")} -> 1000068 | C78: BOTA DE COURO SEM CADARÇO TAM. 38 | D78: PAR | E78: C | F78: 1
A79: SSO | B79: {=IFERROR(INDEX('de para abc'!$A:$A,MATCH($C79,'de para abc'!$B:$B,0)),"N/D")} -> 1000072 | C79: BOTA DE COURO SEM CADARÇO TAM. 42 | D79: PAR | E79: {=IFERROR(INDEX('de para abc'!$C:$C,MATCH($C79,'de para abc'!$B:$B,0)),"N/D")} -> C | F79: 1
A80: SSO | B80: {=IFERROR(INDEX('de para abc'!$A:$A,MATCH($C80,'de para abc'!$B:$B,0)),"N/D")} -> 1000073 | C80: BOTA DE COURO SEM CADARÇO TAM. 43 | D80: PAR | E80: C | F80: 1
...

Sheet CAMPO GRANDE
A1: CONSOLIDADO DE ESTOQUE — CAMPO GRANDE
A2: Itens da unidade Campo Grande. Classe (A/B/C) e código buscados nas abas 'de para abc' e 'de para codigo'.
A4: Categoria | B4: Código | C4: Descrição | D4: Unidade | E4: Classe (A/B/C) | F4: Quantidade | H4: Categoria | I4: Itens | J4: Quantidade
A5: Ferramentaria | B5: 1001719 | C5: ALICATE COMPRESSÃO P/ CABO COAXIAL... | D5: PÇ | E5: {=IFERROR(IF(INDEX('de para abc'!$C:$C,MATCH($B5,'de para abc'!$A:$A,0))=0,"C",INDEX('de para abc'!$C:$C,MATCH($B5,'de para abc'!$A:$A,0))),IFERROR(IF(INDEX('de para abc'!$C:$C,MATCH($C5,'de para abc'!$B:$B,0))=0,"C",INDEX('de para abc'!$C:$C,MATCH($C5,'de para abc'!$B:$B,0))),"C"))} -> B | F5: 0 | H5: Ferramentaria | I5: =COUNTIF($A$5:$A$204,H5) -> 51 | J5: =SUMIF($A$5:$A$204,H5,$F$5:$F$204) -> 667
A6: Ferramentaria | B6: 1000032 | C6: ALICATE DE BICO 6 | D6: PÇ | E6: {=IFERROR(IF(INDEX('de para abc'!$C:$C,MATCH($B6,'de para abc'!$A:$A,0))=0,"C",INDEX('de para abc'!$C:$C,MATCH($B6,'de para abc'!$A:$A,0))),IFERROR(IF(INDEX('de para abc'!$C:$C,MATCH($C6,'de para abc'!$B:$B,0))=0,"C",INDEX('de para abc'!$C:$C,MATCH($C6,'de para abc'!$B:$B,0))),"C"))} -> A | F6: 3 | H6: SSO | I6: =COUNTIF($A$5:$A$204,H6) -> 149 | J6: =SUMIF($A$5:$A$204,H6,$F$5:$F$204) -> 83
A7: Ferramentaria | B7: 1001306 | C7: ALICATE DE GRIMPAR RJ11 / RJ45 | D7: UND | E7: {=IFERROR(IF(INDEX('de para abc'!$C:$C,MATCH($B7,'de para abc'!$A:$A,0))=0,"C",INDEX('de para abc'!$C:$C,MATCH($B7,'de para abc'!$A:$A,0))),IFERROR(IF(INDEX('de para abc'!$C:$C,MATCH($C7,'de para abc'!$B:$B,0))=0,"C",INDEX('de para abc'!$C:$C,MATCH($C7,'de para abc'!$B:$B,0))),"C"))} -> A | F7: 3 | H7: Total | I7: =SUM(I5:I6) -> 200 | J7: =SUM(J5:J6) -> 750
A8: Ferramentaria | B8: 1000036 | C8: ALICATE DE PRESSÃO RG6 | D8: PÇ | E8: {=IFERROR(IF(INDEX('de para abc'!$C:$C,MATCH($B8,'de para abc'!$A:$A,0))=0,"C",INDEX('de para abc'!$C:$C,MATCH($B8,'de para abc'!$A:$A,0))),IFERROR(IF(INDEX('de para abc'!$C:$C,MATCH($C8,'de para abc'!$B:$B,0))=0,"C",INDEX('de para abc'!$C:$C,MATCH($C8,'de para abc'!$B:$B,0))),"C"))} -> B | F8: 2
A9: Ferramentaria | B9: 1000037 | C9: ALICATE DECAPADOR DE FIBRA OPTICA | D9: PÇ | E9: {=IFERROR(IF(INDEX('de para abc'!$C:$C,MATCH($B9,'de para abc'!$A:$A,0))=0,"C",INDEX('de para abc'!$C:$C,MATCH($B9,'de para abc'!$A:$A,0))),IFERROR(IF(INDEX('de para abc'!$C:$C,MATCH($C9,'de para abc'!$B:$B,0))=0,"C",INDEX('de para abc'!$C:$C,MATCH($C9,'de para abc'!$B:$B,0))),"C"))} -> A | F9: 1
A10: Ferramentaria | B10: 9000028 | C10: ALICATE DECAPADOR FIBRA OPT (DROP FLAT) P-22 | D10: PÇ | E10: {=IFERROR(IF(INDEX('de para abc'!$C:$C,MATCH($B10,'de para abc'!$A:$A,0))=0,"C",INDEX('de para abc'!$C:$C,MATCH($B10,'de para abc'!$A:$A,0))),IFERROR(IF(INDEX('de para abc'!$C:$C,MATCH($C10,'de para abc'!$B:$B,0))=0,"C",INDEX('de para abc'!$C:$C,MATCH($C10,'de para abc'!$B:$B,0))),"C"))} -> C | F10: 1
A11: Ferramentaria | B11: 1000039 | C11: ALICATE UNIVERSAL 8 | D11: PÇ | E11: {=IFERROR(IF(INDEX('de para abc'!$C:$C,MATCH($B11,'de para abc'!$A:$A,0))=0,"C",INDEX('de para abc'!$C:$C,MATCH($B11,'de para abc'!$A:$A,0))),IFERROR(IF(INDEX('de para abc'!$C:$C,MATCH($C11,'de para abc'!$B:$B,0))=0,"C",INDEX('de para abc'!$C:$C,MATCH($C11,'de para abc'!$B:$B,0))),"C"))} -> A | F11: 3
A12: Ferramentaria | B12: 1001455 | C12: APLICADOR DE COLA QUENTE | D12: UN | E12: {=IFERROR(IF(INDEX('de para abc'!$C:$C,MATCH($B12,'de para abc'!$A:$A,0))=0,"C",INDEX('de para abc'!$C:$C,MATCH($B12,'de para abc'!$A:$A,0))),IFERROR(IF(INDEX('de para abc'!$C:$C,MATCH($C12,'de para abc'!$B:$B,0))=0,"C",INDEX('de para abc'!$C:$C,MATCH($C12,'de para abc'!$B:$B,0))),"C"))} -> A | F12: 5
A13: Ferramentaria | B13: 1000048 | C13: BADISCO DIGITAL GANDOLA | D13: PÇ | E13: {=IFERROR(IF(INDEX('de para abc'!$C:$C,MATCH($B13,'de para abc'!$A:$A,0))=0,"C",INDEX('de para abc'!$C:$C,MATCH($B13,'de para abc'!$A:$A,0))),IFERROR(IF(INDEX('de para abc'!$C:$C,MATCH($C13,'de para abc'!$B:$B,0))=0,"C",INDEX('de para abc'!$C:$C,MATCH($C13,'de para abc'!$B:$B,0))),"C"))} -> A | F13: 7
A14: Ferramentaria | B14: 1000049 | C14: BALDE DE LONA | D14: PÇ | E14: {=IFERROR(IF(INDEX('de para abc'!$C:$C,MATCH($B14,'de para abc'!$A:$A,0))=0,"C",INDEX('de para abc'!$C:$C,MATCH($B14,'de para abc'!$A:$A,0))),IFERROR(IF(INDEX('de para abc'!$C:$C,MATCH($C14,'de para abc'!$B:$B,0))=0,"C",INDEX('de para abc'!$C:$C,MATCH($C14,'de para abc'!$B:$B,0))),"C"))} -> A | F14: 0
A15: Ferramentaria | B15: 1001712 | C15: BROCA CHATA MADEIRA 6MM X 150MM | D15: UN | E15: {=IFERROR(IF(INDEX('de para abc'!$C:$C,MATCH($B15,'de para abc'!$A:$A,0))=0,"C",INDEX('de para abc'!$C:$C,MATCH($B15,'de para abc'!$A:$A,0))),IFERROR(IF(INDEX('de para abc'!$C:$C,MATCH($C15,'de para abc'!$B:$B,0))=0,"C",INDEX('de para abc'!$C:$C,MATCH($C15,'de para abc'!$B:$B,0))),"C"))} -> B | F15: 2
A16: Ferramentaria | B16: 1001702 | C16: BROCA CHATA MADEIRA 10 MM X 150 MM | D16: UN | E16: {=IFERROR(IF(INDEX('de para abc'!$C:$C,MATCH($B16,'de para abc'!$A:$A,0))=0,"C",INDEX('de para abc'!$C:$C,MATCH($B16,'de para abc'!$A:$A,0))),IFERROR(IF(INDEX('de para abc'!$C:$C,MATCH($C16,'de para abc'!$B:$B,0))=0,"C",INDEX('de para abc'!$C:$C,MATCH($C16,'de para abc'!$B:$B,0))),"C"))} -> B | F16: 2
A17: Ferramentaria | B17: 1001701 | C17: BROCA CHATA MADEIRA 8 MM X 150 MM | D17: UN | E17: {=IFERROR(IF(INDEX('de para abc'!$C:$C,MATCH($B17,'de para abc'!$A:$A,0))=0,"C",INDEX('de para abc'!$C:$C,MATCH($B17,'de para abc'!$A:$A,0))),IFERROR(IF(INDEX('de para abc'!$C:$C,MATCH($C17,'de para abc'!$B:$B,0))=0,"C",INDEX('de para abc'!$C:$C,MATCH($C17,'de para abc'!$B:$B,0))),"C"))} -> B | F17: 2
A18: Ferramentaria | B18: {=IFERROR(INDEX('de para codigo'!$A:$A,MATCH($C18,'de para codigo'!$B:$B,0)),"N/D")} -> N/D | C18: BROCA CHATA MADEIRA 3/8 Pl | D18: UN | E18: {=IFERROR(IF(INDEX('de para abc'!$C:$C,MATCH($B18,'de para abc'!$A:$A,0))=0,"C",INDEX('de para abc'!$C:$C,MATCH($B18,'de para abc'!$A:$A,0))),IFERROR(IF(INDEX('de para abc'!$C:$C,MATCH($C18,'de para abc'!$B:$B,0))=0,"C",INDEX('de para abc'!$C:$C,MATCH($C18,'de para abc'!$B:$B,0))),"C"))} -> C | F18: 1
A19: Ferramentaria | B19: 1001986 | C19: BROCA 3 PONTAS MADEIRA 8 MM | D19: UN | E19: {=IFERROR(IF(INDEX('de para abc'!$C:$C,MATCH($B19,'de para abc'!$A:$A,0))=0,"C",INDEX('de para abc'!$C:$C,MATCH($B19,'de para abc'!$A:$A,0))),IFERROR(IF(INDEX('de para abc'!$C:$C,MATCH($C19,'de para abc'!$B:$B,0))=0,"C",INDEX('de para abc'!$C:$C,MATCH($C19,'de para abc'!$B:$B,0))),"C"))} -> C | F19: 2
A20: Ferramentaria | B20: 1001680 | C20: BROCA DE WIDEA 10MM X 400MM ( LONGA... | D20: PÇ | E20: {=IFERROR(IF(INDEX('de para abc'!$C:$C,MATCH($B20,'de para abc'!$A:$A,0))=0,"C",INDEX('de para abc'!$C:$C,MATCH($B20,'de para abc'!$A:$A,0))),IFERROR(IF(INDEX('de para abc'!$C:$C,MATCH($C20,'de para abc'!$B:$B,0))=0,"C",INDEX('de para abc'!$C:$C,MATCH($C20,'de para abc'!$B:$B,0))),"C"))} -> A | F20: 0
A21: Ferramentaria | B21: 1008890 | C21: CAMERA SONDA ENDOSCOPICA- 5 M | D21: UN | E21: {=IFERROR(IF(INDEX('de para abc'!$C:$C,MATCH($B21,'de para abc'!$A:$A,0))=0,"C",INDEX('de para abc'!$C:$C,MATCH($B21,'de para abc'!$A:$A,0))),IFERROR(IF(INDEX('de para abc'!$C:$C,MATCH($C21,'de para abc'!$B:$B,0))=0,"C",INDEX('de para abc'!$C:$C,MATCH($C21,'de para abc'!$B:$B,0))),"C"))} -> C | F21: 7
A22: Ferramentaria | B22: 1001667 | C22: CANETA P/ LIMPEZA DE CONECTOR 2.5m... | D22: UN | E22: {=IFERROR(IF(INDEX('de para abc'!$C:$C,MATCH($B22,'de para abc'!$A:$A,0))=0,"C",INDEX('de para abc'!$C:$C,MATCH($B22,'de para abc'!$A:$A,0))),IFERROR(IF(INDEX('de para abc'!$C:$C,MATCH($C22,'de para abc'!$B:$B,0))=0,"C",INDEX('de para abc'!$C:$C,MATCH($C22,'de para abc'!$B:$B,0))),"C"))} -> A | F22: 20
A23: Ferramentaria | B23: 1001122 | C23: CANETA OPTICA - VISUAL FAULT RY V31... | D23: PÇ | E23: {=IFERROR(IF(INDEX('de para abc'!$C:$C,MATCH($B23,'de para abc'!$A:$A,0))=0,"C",INDEX('de para abc'!$C:$C,MATCH($B23,'de para abc'!$A:$A,0))),IFERROR(IF(INDEX('de para abc'!$C:$C,MATCH($C23,'de para abc'!$B:$B,0))=0,"C",INDEX('de para abc'!$C:$C,MATCH($C23,'de para abc'!$B:$B,0))),"C"))} -> A | F23: 2
A24: Ferramentaria | B24: 1001146 | C24: CHAVE DE ARMÁRIO TRIANGULAR | D24: PÇ | E24: {=IFERROR(IF(INDEX('de para abc'!$C:$C,MATCH($B24,'de para abc'!$A:$A,0))=0,"C",INDEX('de para abc'!$C:$C,MATCH($B24,'de para abc'!$A:$A,0))),IFERROR(IF(INDEX('de para abc'!$C:$C,MATCH($C24,'de para abc'!$B:$B,0))=0,"C",INDEX('de para abc'!$C:$C,MATCH($C24,'de para abc'!$B:$B,0))),"C"))} -> B | F24: 9
A25: Ferramentaria | B25: 1000184 | C25: CHAVE DE FENDA MEDIA | D25: UND | E25: {=IFERROR(IF(INDEX('de para abc'!$C:$C,MATCH($B25,'de para abc'!$A:$A,0))=0,"C",INDEX('de para abc'!$C:$C,MATCH($B25,'de para abc'!$A:$A,0))),IFERROR(IF(INDEX('de para abc'!$C:$C,MATCH($C25,'de para abc'!$B:$B,0))=0,"C",INDEX('de para abc'!$C:$C,MATCH($C25,'de para abc'!$B:$B,0))),"C"))} -> A | F25: 8
A26: Ferramentaria | B26: 1000185 | C26: CHAVE DE FENDA PEQUENA | D26: UND | E26: {=IFERROR(IF(INDEX('de para abc'!$C:$C,MATCH($B26,'de para abc'!$A:$A,0))=0,"C",INDEX('de para abc'!$C:$C,MATCH($B26,'de para abc'!$A:$A,0))),IFERROR(IF(INDEX('de para abc'!$C:$C,MATCH($C26,'de para abc'!$B:$B,0))=0,"C",INDEX('de para abc'!$C:$C,MATCH($C26,'de para abc'!$B:$B,0))),"C"))} -> A | F26: 3
A27: Ferramentaria | B27: 1000183 | C27: CHAVE DE FENDA GRANDE | D27: UND | E27: {=IFERROR(IF(INDEX('de para abc'!$C:$C,MATCH($B27,'de para abc'!$A:$A,0))=0,"C",INDEX('de para abc'!$C:$C,MATCH($B27,'de para abc'!$A:$A,0))),IFERROR(IF(INDEX('de para abc'!$C:$C,MATCH($C27,'de para abc'!$B:$B,0))=0,"C",INDEX('de para abc'!$C:$C,MATCH($C27,'de para abc'!$B:$B,0))),"C"))} -> A | F27: 3
A28: Ferramentaria | B28: 1006116 | C28: CHAVE GTP TRAVA E DESTRAVA CURTA | D28: PÇ | E28: {=IFERROR(IF(INDEX('de para abc'!$C:$C,MATCH($B28,'de para abc'!$A:$A,0))=0,"C",INDEX('de para abc'!$C:$C,MATCH($B28,'de para abc'!$A:$A,0))),IFERROR(IF(INDEX('de para abc'!$C:$C,MATCH($C28,'de para abc'!$B:$B,0))=0,"C",INDEX('de para abc'!$C:$C,MATCH($C28,'de para abc'!$B:$B,0))),"C"))} -> B | F28: 1
A29: Ferramentaria | B29: {=IFERROR(INDEX('de para codigo'!$A:$A,MATCH($C29,'de para codigo'!$B:$B,0)),"N/D")} -> N/D | C29: CHAVE GTP TRAVA E DESTRAVA LONGA | D29: PÇ | E29: {=IFERROR(IF(INDEX('de para abc'!$C:$C,MATCH($B29,'de para abc'!$A:$A,0))=0,"C",INDEX('de para abc'!$C:$C,MATCH($B29,'de para abc'!$A:$A,0))),IFERROR(IF(INDEX('de para abc'!$C:$C,MATCH($C29,'de para abc'!$B:$B,0))=0,"C",INDEX('de para abc'!$C:$C,MATCH($C29,'de para abc'!$B:$B,0))),"C"))} -> C | F29: 6
A30: Ferramentaria | B30: 1001707 | C30: CHAVE MINI TRAP ST1 P/ CONECTOR RG ... | D30: UN | E30: {=IFERROR(IF(INDEX('de para abc'!$C:$C,MATCH($B30,'de para abc'!$A:$A,0))=0,"C",INDEX('de para abc'!$C:$C,MATCH($B30,'de para abc'!$A:$A,0))),IFERROR(IF(INDEX('de para abc'!$C:$C,MATCH($C30,'de para abc'!$B:$B,0))=0,"C",INDEX('de para abc'!$C:$C,MATCH($C30,'de para abc'!$B:$B,0))),"C"))} -> B | F30: 3
A31: Ferramentaria | B31: 1000195 | C31: CHAVE P/ CAIXA SUBTERRANEA | D31: PÇ | E31: {=IFERROR(IF(INDEX('de para abc'!$C:$C,MATCH($B31,'de para abc'!$A:$A,0))=0,"C",INDEX('de para abc'!$C:$C,MATCH($B31,'de para abc'!$A:$A,0))),IFERROR(IF(INDEX('de para abc'!$C:$C,MATCH($C31,'de para abc'!$B:$B,0))=0,"C",INDEX('de para abc'!$C:$C,MATCH($C31,'de para abc'!$B:$B,0))),"C"))} -> A | F31: 0
A32: Ferramentaria | B32: 1000196 | C32: CHAVE PHILIPS GRANDE | D32: UND | E32: {=IFERROR(IF(INDEX('de para abc'!$C:$C,MATCH($B32,'de para abc'!$A:$A,0))=0,"C",INDEX('de para abc'!$C:$C,MATCH($B32,'de para abc'!$A:$A,0))),IFERROR(IF(INDEX('de para abc'!$C:$C,MATCH($C32,'de para abc'!$B:$B,0))=0,"C",INDEX('de para abc'!$C:$C,MATCH($C32,'de para abc'!$B:$B,0))),"C"))} -> A | F32: 1
A33: Ferramentaria | B33: 1000197 | C33: CHAVE PHILIPS MEDIA | D33: UND | E33: {=IFERROR(IF(INDEX('de para abc'!$C:$C,MATCH($B33,'de para abc'!$A:$A,0))=0,"C",INDEX('de para abc'!$C:$C,MATCH($B33,'de para abc'!$A:$A,0))),IFERROR(IF(INDEX('de para abc'!$C:$C,MATCH($C33,'de para abc'!$B:$B,0))=0,"C",INDEX('de para abc'!$C:$C,MATCH($C33,'de para abc'!$B:$B,0))),"C"))} -> A | F33: 7
A34: Ferramentaria | B34: 1000198 | C34: CHAVE PHILIPS PEQUENA | D34: UND | E34: {=IFERROR(IF(INDEX('de para abc'!$C:$C,MATCH($B34,'de para abc'!$A:$A,0))=0,"C",INDEX('de para abc'!$C:$C,MATCH($B34,'de para abc'!$A:$A,0))),IFERROR(IF(INDEX('de para abc'!$C:$C,MATCH($C34,'de para abc'!$B:$B,0))=0,"C",INDEX('de para abc'!$C:$C,MATCH($C34,'de para abc'!$B:$B,0))),"C"))} -> A | F34: 3
A35: Ferramentaria | B35: 1001741 | C35: CHAVE TORQUE PARA CONECTOR 20K | D35: UND | E35: {=IFERROR(IF(INDEX('de para abc'!$C:$C,MATCH($B35,'de para abc'!$A:$A,0))=0,"C",INDEX('de para abc'!$C:$C,MATCH($B35,'de para abc'!$A:$A,0))),IFERROR(IF(INDEX('de para abc'!$C:$C,MATCH($C35,'de para abc'!$B:$B,0))=0,"C",INDEX('de para abc'!$C:$C,MATCH($C35,'de para abc'!$B:$B,0))),"C"))} -> A | F35: 5
A36: Ferramentaria | B36: 1001045 | C36: CLIVADOR FIBER CLEAVER | D36: PÇ | E36: {=IFERROR(IF(INDEX('de para abc'!$C:$C,MATCH($B36,'de para abc'!$A:$A,0))=0,"C",INDEX('de para abc'!$C:$C,MATCH($B36,'de para abc'!$A:$A,0))),IFERROR(IF(INDEX('de para abc'!$C:$C,MATCH($C36,'de para abc'!$B:$B,0))=0,"C",INDEX('de para abc'!$C:$C,MATCH($C36,'de para abc'!$B:$B,0))),"C"))} -> A | F36: 2
A37: Ferramentaria | B37: 1001488 | C37: ESCADA 5 DEGRAUS DOMESTICA | D37: UN | E37: {=IFERROR(IF(INDEX('de para abc'!$C:$C,MATCH($B37,'de para abc'!$A:$A,0))=0,"C",INDEX('de para abc'!$C:$C,MATCH($B37,'de para abc'!$A:$A,0))),IFERROR(IF(INDEX('de para abc'!$C:$C,MATCH($C37,'de para abc'!$B:$B,0))=0,"C",INDEX('de para abc'!$C:$C,MATCH($C37,'de para abc'!$B:$B,0))),"C"))} -> A | F37: 2
A38: Ferramentaria | B38: 1000243 | C38: ESCADA DE FIBRA EXTENSIVEL 3,60 X 6,00 | D38: UND | E38: {=IFERROR(IF(INDEX('de para abc'!$C:$C,MATCH($B38,'de para abc'!$A:$A,0))=0,"C",INDEX('de para abc'!$C:$C,MATCH($B38,'de para abc'!$A:$A,0))),IFERROR(IF(INDEX('de para abc'!$C:$C,MATCH($C38,'de para abc'!$B:$B,0))=0,"C",INDEX('de para abc'!$C:$C,MATCH($C38,'de para abc'!$B:$B,0))),"C"))} -> A | F38: 1
A39: Ferramentaria | B39: 1000481 | C39: DECAPADOR DE CABOS | D39: UND | E39: {=IFERROR(IF(INDEX('de para abc'!$C:$C,MATCH($B39,'de para abc'!$A:$A,0))=0,"C",INDEX('de para abc'!$C:$C,MATCH($B39,'de para abc'!$A:$A,0))),IFERROR(IF(INDEX('de para abc'!$C:$C,MATCH($C39,'de para abc'!$B:$B,0))=0,"C",INDEX('de para abc'!$C:$C,MATCH($C39,'de para abc'!$B:$B,0))),"C"))} -> B | F39: 3
A40: Ferramentaria | B40: 1001264 | C40: FERRO DE ABRIR CAIXA TIPO T | D40: UN | E40: {=IFERROR(IF(INDEX('de para abc'!$C:$C,MATCH($B40,'de para abc'!$A:$A,0))=0,"C",INDEX('de para abc'!$C:$C,MATCH($B40,'de para abc'!$A:$A,0))),IFERROR(IF(INDEX('de para abc'!$C:$C,MATCH($C40,'de para abc'!$B:$B,0))=0,"C",INDEX('de para abc'!$C:$C,MATCH($C40,'de para abc'!$B:$B,0))),"C"))} -> A | F40: 2
A41: Ferramentaria | B41: 1000262 | C41: FERRO DE CAIXA TIPO J | D41: UN | E41: {=IFERROR(IF(INDEX('de para abc'!$C:$C,MATCH($B41,'de para abc'!$A:$A,0))=0,"C",INDEX('de para abc'!$C:$C,MATCH($B41,'de para abc'!$A:$A,0))),IFERROR(IF(INDEX('de para abc'!$C:$C,MATCH($C41,'de para abc'!$B:$B,0))=0,"C",INDEX('de para abc'!$C:$C,MATCH($C41,'de para abc'!$B:$B,0))),"C"))} -> C | F41: 12
...

Sheet NITEROI
A1: CONSOLIDADO DE ESTOQUE — NITEROI
A2: Itens da unidade Niterói. Classe (A/B/C) e código buscados nas abas 'de para abc' e 'de para codigo'.
