Workbook

Sheet CONSOLIDADO
A1: Data | B1: Base | C1: Projeto | D1: Código | E1: Descrição | F1: Unidade | G1: Valor Unitario | H1: Saldo | I1: Total Real | J1: Classe ABC
A2: 46192 | B2: RIO DE JANEIRO | C2: FERRAM. REG. RJ | D2: 1001663 | E2: ADAPTADOR P/ CONECTOR SC-APC (POWER METER) | F2: UN | G2: 2 | H2: 118 | I2: 236 | J2: =IF(C2="","",_xlfn.XLOOKUP(UPPER(TRIM(SUBSTITUTE(SUBSTITUTE(SUBSTITUTE(TRIM(C2),"."," "),"Â","A"),"Ç","C")))&"|"&UPPER(TRIM(D2)),ABC_REF!$A:$A,ABC_REF!$B:$B,_xlfn.XLOOKUP(UPPER(TRIM(D2)),ABC_REF!$D:$D,ABC_REF!$E:$E,_xlfn.XLOOKUP(UPPER(TRIM(E2)),ABC_REF!$G:$G,ABC_REF!$H:$H,"C")))) -> A
A3: 46192 | B3: RIO DE JANEIRO | C3: FERRAM. REG. RJ | D3: 1000021 | E3: ALAVANCA DE AÇO 1,45MTS | F3: PÇ | G3: 142 | H3: 15 | I3: 2130 | J3: =IF(C3="","",_xlfn.XLOOKUP(UPPER(TRIM(SUBSTITUTE(SUBSTITUTE(SUBSTITUTE(TRIM(C3),"."," "),"Â","A"),"Ç","C")))&"|"&UPPER(TRIM(D3)),ABC_REF!$A:$A,ABC_REF!$B:$B,_xlfn.XLOOKUP(UPPER(TRIM(D3)),ABC_REF!$D:$D,ABC_REF!$E:$E,_xlfn.XLOOKUP(UPPER(TRIM(E3)),ABC_REF!$G:$G,ABC_REF!$H:$H,"C")))) -> C
A4: 46192 | B4: RIO DE JANEIRO | C4: FERRAM. REG. RJ | D4: 1002304 | E4: ALCOOL ISOPROPILICO LT | F4: LT | G4: 22.9 | H4: 35 | I4: 801.5 | J4: =IF(C4="","",_xlfn.XLOOKUP(UPPER(TRIM(SUBSTITUTE(SUBSTITUTE(SUBSTITUTE(TRIM(C4),"."," "),"Â","A"),"Ç","C")))&"|"&UPPER(TRIM(D4)),ABC_REF!$A:$A,ABC_REF!$B:$B,_xlfn.XLOOKUP(UPPER(TRIM(D4)),ABC_REF!$D:$D,ABC_REF!$E:$E,_xlfn.XLOOKUP(UPPER(TRIM(E4)),ABC_REF!$G:$G,ABC_REF!$H:$H,"C")))) -> C
A5: 46192 | B5: RIO DE JANEIRO | C5: FERRAM. REG. RJ | D5: 1000031 | E5: ALCOOL ISOPROPILICO 1000ML | F5: LT | G5: 28.9 | H5: 20 | I5: 578 | J5: =IF(C5="","",_xlfn.XLOOKUP(UPPER(TRIM(SUBSTITUTE(SUBSTITUTE(SUBSTITUTE(TRIM(C5),"."," "),"Â","A"),"Ç","C")))&"|"&UPPER(TRIM(D5)),ABC_REF!$A:$A,ABC_REF!$B:$B,_xlfn.XLOOKUP(UPPER(TRIM(D5)),ABC_REF!$D:$D,ABC_REF!$E:$E,_xlfn.XLOOKUP(UPPER(TRIM(E5)),ABC_REF!$G:$G,ABC_REF!$H:$H,"C")))) -> A
A6: 46192 | B6: RIO DE JANEIRO | C6: FERRAM. REG. RJ | D6: 1001915 | E6: ALCOOL ISOPROPILICO 250ML | F6: UN | G6: 24.21 | H6: 5 | I6: 121.05 | J6: =IF(C6="","",_xlfn.XLOOKUP(UPPER(TRIM(SUBSTITUTE(SUBSTITUTE(SUBSTITUTE(TRIM(C6),"."," "),"Â","A"),"Ç","C")))&"|"&UPPER(TRIM(D6)),ABC_REF!$A:$A,ABC_REF!$B:$B,_xlfn.XLOOKUP(UPPER(TRIM(D6)),ABC_REF!$D:$D,ABC_REF!$E:$E,_xlfn.XLOOKUP(UPPER(TRIM(E6)),ABC_REF!$G:$G,ABC_REF!$H:$H,"C")))) -> C
A7: 46192 | B7: RIO DE JANEIRO | C7: FERRAM. REG. RJ | D7: 1001268 | E7: ALICATE AMPERÍMETRO | F7: UND | G7: 67 | H7: 1 | I7: 67 | J7: =IF(C7="","",_xlfn.XLOOKUP(UPPER(TRIM(SUBSTITUTE(SUBSTITUTE(SUBSTITUTE(TRIM(C7),"."," "),"Â","A"),"Ç","C")))&"|"&UPPER(TRIM(D7)),ABC_REF!$A:$A,ABC_REF!$B:$B,_xlfn.XLOOKUP(UPPER(TRIM(D7)),ABC_REF!$D:$D,ABC_REF!$E:$E,_xlfn.XLOOKUP(UPPER(TRIM(E7)),ABC_REF!$G:$G,ABC_REF!$H:$H,"C")))) -> C
A8: 46192 | B8: RIO DE JANEIRO | C8: FERRAM. REG. RJ | D8: 1001719 | E8: ALICATE COMPRESSÃO P/ CABO COAXIAL RG11 | F8: PÇ | G8: 59 | H8: 34 | I8: 2006 | J8: =IF(C8="","",_xlfn.XLOOKUP(UPPER(TRIM(SUBSTITUTE(SUBSTITUTE(SUBSTITUTE(TRIM(C8),"."," "),"Â","A"),"Ç","C")))&"|"&UPPER(TRIM(D8)),ABC_REF!$A:$A,ABC_REF!$B:$B,_xlfn.XLOOKUP(UPPER(TRIM(D8)),ABC_REF!$D:$D,ABC_REF!$E:$E,_xlfn.XLOOKUP(UPPER(TRIM(E8)),ABC_REF!$G:$G,ABC_REF!$H:$H,"C")))) -> A
A9: 46192 | B9: RIO DE JANEIRO | C9: FERRAM. REG. RJ | D9: 1001962 | E9: ALICATE CORTA E DESENCAPA CABO (BANANA) | F9: UNID | G9: 75 | H9: 2 | I9: 150 | J9: =IF(C9="","",_xlfn.XLOOKUP(UPPER(TRIM(SUBSTITUTE(SUBSTITUTE(SUBSTITUTE(TRIM(C9),"."," "),"Â","A"),"Ç","C")))&"|"&UPPER(TRIM(D9)),ABC_REF!$A:$A,ABC_REF!$B:$B,_xlfn.XLOOKUP(UPPER(TRIM(D9)),ABC_REF!$D:$D,ABC_REF!$E:$E,_xlfn.XLOOKUP(UPPER(TRIM(E9)),ABC_REF!$G:$G,ABC_REF!$H:$H,"C")))) -> C
A10: 46192 | B10: RIO DE JANEIRO | C10: FERRAM. REG. RJ | D10: 1000032 | E10: ALICATE DE BICO 6 | F10: PÇ | G10: 35 | H10: 90 | I10: 3150 | J10: =IF(C10="","",_xlfn.XLOOKUP(UPPER(TRIM(SUBSTITUTE(SUBSTITUTE(SUBSTITUTE(TRIM(C10),"."," "),"Â","A"),"Ç","C")))&"|"&UPPER(TRIM(D10)),ABC_REF!$A:$A,ABC_REF!$B:$B,_xlfn.XLOOKUP(UPPER(TRIM(D10)),ABC_REF!$D:$D,ABC_REF!$E:$E,_xlfn.XLOOKUP(UPPER(TRIM(E10)),ABC_REF!$G:$G,ABC_REF!$H:$H,"C")))) -> A
A11: 46192 | B11: RIO DE JANEIRO | C11: FERRAM. REG. RJ | D11: 1000033 | E11: ALICATE DE CORTE 6 | F11: PÇ | G11: 35 | H11: 14 | I11: 490 | J11: =IF(C11="","",_xlfn.XLOOKUP(UPPER(TRIM(SUBSTITUTE(SUBSTITUTE(SUBSTITUTE(TRIM(C11),"."," "),"Â","A"),"Ç","C")))&"|"&UPPER(TRIM(D11)),ABC_REF!$A:$A,ABC_REF!$B:$B,_xlfn.XLOOKUP(UPPER(TRIM(D11)),ABC_REF!$D:$D,ABC_REF!$E:$E,_xlfn.XLOOKUP(UPPER(TRIM(E11)),ABC_REF!$G:$G,ABC_REF!$H:$H,"C")))) -> A
A12: 46192 | B12: RIO DE JANEIRO | C12: FERRAM. REG. RJ | D12: 1001306 | E12: ALICATE DE GRIMPAR RJ11 / RJ45 | F12: UND | G12: 30 | H12: 48 | I12: 1440 | J12: =IF(C12="","",_xlfn.XLOOKUP(UPPER(TRIM(SUBSTITUTE(SUBSTITUTE(SUBSTITUTE(TRIM(C12),"."," "),"Â","A"),"Ç","C")))&"|"&UPPER(TRIM(D12)),ABC_REF!$A:$A,ABC_REF!$B:$B,_xlfn.XLOOKUP(UPPER(TRIM(D12)),ABC_REF!$D:$D,ABC_REF!$E:$E,_xlfn.XLOOKUP(UPPER(TRIM(E12)),ABC_REF!$G:$G,ABC_REF!$H:$H,"C")))) -> A
A13: 46192 | B13: RIO DE JANEIRO | C13: FERRAM. REG. RJ | D13: 1000035 | E13: ALICATE DE INSERÇÃO TERMINAL (BARGOA) | F13: UND | G13: 32.5 | H13: 171 | I13: 5557.5 | J13: =IF(C13="","",_xlfn.XLOOKUP(UPPER(TRIM(SUBSTITUTE(SUBSTITUTE(SUBSTITUTE(TRIM(C13),"."," "),"Â","A"),"Ç","C")))&"|"&UPPER(TRIM(D13)),ABC_REF!$A:$A,ABC_REF!$B:$B,_xlfn.XLOOKUP(UPPER(TRIM(D13)),ABC_REF!$D:$D,ABC_REF!$E:$E,_xlfn.XLOOKUP(UPPER(TRIM(E13)),ABC_REF!$G:$G,ABC_REF!$H:$H,"C")))) -> C
... A36: 46192 | B36: RIO DE JANEIRO | C36: FERRAM. REG. RJ | D36: 1002051 | E36: BOBINA PICOTADA 40X60 | F36: UN | G36: 52.05 | H36: 16 | I36: 832.8 | J36: =IF(C36="","",_xlfn.XLOOKUP(UPPER(TRIM(SUBSTITUTE(SUBSTITUTE(SUBSTITUTE(TRIM(C36),"."," "),"Â","A"),"Ç","C")))&"|"&UPPER(TRIM(D36)),ABC_REF!$A:$A,ABC_REF!$B:$B,_xlfn.XLOOKUP(UPPER(TRIM(D36)),ABC_REF!$D:$D,ABC_REF!$E:$E,_xlfn.XLOOKUP(UPPER(TRIM(E36)),ABC_REF!$G:$G,ABC_REF!$H:$H,"C")))) -> C
A37: 46192 | B37: RIO DE JANEIRO | C37: FERRAM. REG. RJ | D37: 1002151 | E37: BOCAL | G37: 1.8 | H37: 29 | I37: 52.2 | J37: =IF(C37="","",_xlfn.XLOOKUP(UPPER(TRIM(SUBSTITUTE(SUBSTITUTE(SUBSTITUTE(TRIM(C37),"."," "),"Â","A"),"Ç","C")))&"|"&UPPER(TRIM(D37)),ABC_REF!$A:$A,ABC_REF!$B:$B,_xlfn.XLOOKUP(UPPER(TRIM(D37)),ABC_REF!$D:$D,ABC_REF!$E:$E,_xlfn.XLOOKUP(UPPER(TRIM(E37)),ABC_REF!$G:$G,ABC_REF!$H:$H,"C")))) -> C
A38: 46192 | B38: RIO DE JANEIRO | C38: FERRAM. REG. RJ | D38: 1000065 | E38: BOLSA DE LONA | F38: PÇ | G38: 35 | H38: 72 | I38: 2520 | J38: =IF(C38="","",_xlfn.XLOOKUP(UPPER(TRIM(SUBSTITUTE(SUBSTITUTE(SUBSTITUTE(TRIM(C38),"."," "),"Â","A"),"Ç","C")))&"|"&UPPER(TRIM(D38)),ABC_REF!$A:$A,ABC_REF!$B:$B,_xlfn.XLOOKUP(UPPER(TRIM(D38)),ABC_REF!$D:$D,ABC_REF!$E:$E,_xlfn.XLOOKUP(UPPER(TRIM(E38)),ABC_REF!$G:$G,ABC_REF!$H:$H,"C")))) -> A
A39: 46192 | B39: RIO DE JANEIRO | C39: FERRAM. REG. RJ | D39: 1008891 | E39: BROCA 3 PONTAS P/ MADEIRA 10MM | F39: PÇ | G39: 12 | H39: 66 | I39: 792 | J39: =IF(C39="","",_xlfn.XLOOKUP(UPPER(TRIM(SUBSTITUTE(SUBSTITUTE(SUBSTITUTE(TRIM(C39),"."," "),"Â","A"),"Ç","C")))&"|"&UPPER(TRIM(D39)),ABC_REF!$A:$A,ABC_REF!$B:$B,_xlfn.XLOOKUP(UPPER(TRIM(D39)),ABC_REF!$D:$D,ABC_REF!$E:$E,_xlfn.XLOOKUP(UPPER(TRIM(E39)),ABC_REF!$G:$G,ABC_REF!$H:$H,"C")))) -> C
A40: 46192 | B40: RIO DE JANEIRO | C40: FERRAM. REG. RJ | D40: 1001986 | E40: BROCA 3 PONTAS P/ MADEIRA 8MM | F40: UN | G40: 17.3333 | H40: 42 | I40: 727.9986 | J40: =IF(C40="","",_xlfn.XLOOKUP(UPPER(TRIM(SUBSTITUTE(SUBSTITUTE(SUBSTITUTE(TRIM(C40),"."," "),"Â","A"),"Ç","C")))&"|"&UPPER(TRIM(D40)),ABC_REF!$A:$A,ABC_REF!$B:$B,_xlfn.XLOOKUP(UPPER(TRIM(D40)),ABC_REF!$D:$D,ABC_REF!$E:$E,_xlfn.XLOOKUP(UPPER(TRIM(E40)),ABC_REF!$G:$G,ABC_REF!$H:$H,"C")))) -> C
A41: 46192 | B41: RIO DE JANEIRO | C41: FERRAM. REG. RJ | D41: 1002284 | E41: BROCA AÇO RAPIDO 4MM | F41: UN | G41: 1.9 | H41: 37 | I41: 70.3 | J41: =IF(C41="","",_xlfn.XLOOKUP(UPPER(TRIM(SUBSTITUTE(SUBSTITUTE(SUBSTITUTE(TRIM(C41),"."," "),"Â","A"),"Ç","C")))&"|"&UPPER(TRIM(D41)),ABC_REF!$A:$A,ABC_REF!$B:$B,_xlfn.XLOOKUP(UPPER(TRIM(D41)),ABC_REF!$D:$D,ABC_REF!$E:$E,_xlfn.XLOOKUP(UPPER(TRIM(E41)),ABC_REF!$G:$G,ABC_REF!$H:$H,"C")))) -> C
A42: 46192 | B42: RIO DE JANEIRO | C42: FERRAM. REG. RJ | D42: 1001456 | E42: BROCA AÇO RAPIDO 6MM | F42: UN | G42: 2.9 | H42: 21 | I42: 60.9 | J42: =IF(C42="","",_xlfn.XLOOKUP(UPPER(TRIM(SUBSTITUTE(SUBSTITUTE(SUBSTITUTE(TRIM(C42),"."," "),"Â","A"),"Ç","C")))&"|"&UPPER(TRIM(D42)),ABC_REF!$A:$A,ABC_REF!$B:$B,_xlfn.XLOOKUP(UPPER(TRIM(D42)),ABC_REF!$D:$D,ABC_REF!$E:$E,_xlfn.XLOOKUP(UPPER(TRIM(E42)),ABC_REF!$G:$G,ABC_REF!$H:$H,"C")))) -> B
A43: 46192 | B43: RIO DE JANEIRO | C43: FERRAM. REG. RJ | D43: 1002244 | E43: BROCA AÇO RAPIDO 8MM | F43: UN | G43: 8 | H43: 9 | I43: 72 | J43: =IF(C43="","",_xlfn.XLOOKUP(UPPER(TRIM(SUBSTITUTE(SUBSTITUTE(SUBSTITUTE(TRIM(C43),"."," "),"Â","A"),"Ç","C")))&"|"&UPPER(TRIM(D43)),ABC_REF!$A:$A,ABC_REF!$B:$B,_xlfn.XLOOKUP(UPPER(TRIM(D43)),ABC_REF!$D:$D,ABC_REF!$E:$E,_xlfn.XLOOKUP(UPPER(TRIM(E43)),ABC_REF!$G:$G,ABC_REF!$H:$H,"C")))) -> C
A44: 46192 | B44: RIO DE JANEIRO | C44: FERRAM. REG. RJ | D44: 1001712 | E44: BROCA CHATA MADEIRA 6MM X 150MM | F44: UN | G44: 11 | H44: 50 | I44: 550 | J44: =IF(C44="","",_xlfn.XLOOKUP(UPPER(TRIM(SUBSTITUTE(SUBSTITUTE(SUBSTITUTE(TRIM(C44),"."," "),"Â","A"),"Ç","C")))&"|"&UPPER(TRIM(D44)),ABC_REF!$A:$A,ABC_REF!$B:$B,_xlfn.XLOOKUP(UPPER(TRIM(D44)),ABC_REF!$D:$D,ABC_REF!$E:$E,_xlfn.XLOOKUP(UPPER(TRIM(E44)),ABC_REF!$G:$G,ABC_REF!$H:$H,"C")))) -> C
A45: 46192 | B45: RIO DE JANEIRO | C45: FERRAM. REG. RJ | D45: 1001702 | E45: BROCA CHATA MADEIRA 10 MM X 150 MM | F45: UN | G45: 12 | H45: 25 | I45: 300 | J45: =IF(C45="","",_xlfn.XLOOKUP(UPPER(TRIM(SUBSTITUTE(SUBSTITUTE(SUBSTITUTE(TRIM(C45),"."," "),"Â","A"),"Ç","C")))&"|"&UPPER(TRIM(D45)),ABC_REF!$A:$A,ABC_REF!$B:$B,_xlfn.XLOOKUP(UPPER(TRIM(D45)),ABC_REF!$D:$D,ABC_REF!$E:$E,_xlfn.XLOOKUP(UPPER(TRIM(E45)),ABC_REF!$G:$G,ABC_REF!$H:$H,"C")))) -> A
A46: 46192 | B46: RIO DE JANEIRO | C46: FERRAM. REG. RJ | D46: 1001701 | E46: BROCA CHATA MADEIRA 8 MM X 150 MM | F46: UN | G46: 13 | H46: 32 | I46: 416 | J46: =IF(C46="","",_xlfn.XLOOKUP(UPPER(TRIM(SUBSTITUTE(SUBSTITUTE(SUBSTITUTE(TRIM(C46),"."," "),"Â","A"),"Ç","C")))&"|"&UPPER(TRIM(D46)),ABC_REF!$A:$A,ABC_REF!$B:$B,_xlfn.XLOOKUP(UPPER(TRIM(D46)),ABC_REF!$D:$D,ABC_REF!$E:$E,_xlfn.XLOOKUP(UPPER(TRIM(E46)),ABC_REF!$G:$G,ABC_REF!$H:$H,"C")))) -> B
A47: 46192 | B47: RIO DE JANEIRO | C47: FERRAM. REG. RJ | D47: 1001686 | E47: BROCA DE AÇO RÁPIDO 8MM | F47: UND | G47: 8 | H47: 61 | I47: 488 | J47: =IF(C47="","",_xlfn.XLOOKUP(UPPER(TRIM(SUBSTITUTE(SUBSTITUTE(SUBSTITUTE(TRIM(C47),"."," "),"Â","A"),"Ç","C")))&"|"&UPPER(TRIM(D47)),ABC_REF!$A:$A,ABC_REF!$B:$B,_xlfn.XLOOKUP(UPPER(TRIM(D47)),ABC_REF!$D:$D,ABC_REF!$E:$E,_xlfn.XLOOKUP(UPPER(TRIM(E47)),ABC_REF!$G:$G,ABC_REF!$H:$H,"C")))) -> C
A48: 46192 | B48: RIO DE JANEIRO | C48: FERRAM. REG. RJ | D48: 1001680 | E48: BROCA DE WIDEA 10MM X 400MM ( LONGA) | F48: PÇ | G48: 14.9 | H48: 61 | I48: 908.9 | J48: =IF(C48="","",_xlfn.XLOOKUP(UPPER(TRIM(SUBSTITUTE(SUBSTITUTE(SUBSTITUTE(TRIM(C48),"."," "),"Â","A"),"Ç","C")))&"|"&UPPER(TRIM(D48)),ABC_REF!$A:$A,ABC_REF!$B:$B,_xlfn.XLOOKUP(UPPER(TRIM(D48)),ABC_REF!$D:$D,ABC_REF!$E:$E,_xlfn.XLOOKUP(UPPER(TRIM(E48)),ABC_REF!$G:$G,ABC_REF!$H:$H,"C")))) -> A
A49: 46192 | B49: RIO DE JANEIRO | C49: FERRAM. REG. RJ | D49: 1001941 | E49: BROCA DE WIDEA 8MM X 400MM (LONGA) | F49: UNID | G49: 3.8 | H49: 133 | I49: 505.4 | J49: =IF(C49="","",_xlfn.XLOOKUP(UPPER(TRIM(SUBSTITUTE(SUBSTITUTE(SUBSTITUTE(TRIM(C49),"."," "),"Â","A"),"Ç","C")))&"|"&UPPER(TRIM(D49)),ABC_REF!$A:$A,ABC_REF!$B:$B,_xlfn.XLOOKUP(UPPER(TRIM(D49)),ABC_REF!$D:$D,ABC_REF!$E:$E,_xlfn.XLOOKUP(UPPER(TRIM(E49)),ABC_REF!$G:$G,ABC_REF!$H:$H,"C")))) -> C
... A164: 46192 | B164: RIO DE JANEIRO | C164: FERRAM. REG. RJ | D164: 1002270 | E164: FURADEIRA HAMMER 700W | F164: UN | G164: 140 | H164: 31 | I164: 4340 | J164: =IF(C164="","",_xlfn.XLOOKUP(UPPER(TRIM(SUBSTITUTE(SUBSTITUTE(SUBSTITUTE(TRIM(C164),"."," "),"Â","A"),"Ç","C")))&"|"&UPPER(TRIM(D164)),ABC_REF!$A:$A,ABC_REF!$B:$B,_xlfn.XLOOKUP(UPPER(TRIM(D164)),ABC_REF!$D:$D,ABC_REF!$E:$E,_xlfn.XLOOKUP(UPPER(TRIM(E164)),ABC_REF!$G:$G,ABC_REF!$H:$H,"C")))) -> A
A165: 46192 | B165: RIO DE JANEIRO | C165: FERRAM. REG. RJ | D165: 1001940 | E165: FURADEIRA SKIL MODELO 6662 550W 127V | F165: UND | G165: 227.3 | H165: 1 | J165: =IF(C165="","",_xlfn.XLOOKUP(UPPER(TRIM(SUBSTITUTE(SUBSTITUTE(SUBSTITUTE(TRIM(C165),"."," "),"Â","A"),"Ç","C")))&"|"&UPPER(TRIM(D165)),ABC_REF!$A:$A,ABC_REF!$B:$B,_xlfn.XLOOKUP(UPPER(TRIM(D165)),ABC_REF!$D:$D,ABC_REF!$E:$E,_xlfn.XLOOKUP(UPPER(TRIM(E165)),ABC_REF!$G:$G,ABC_REF!$H:$H,"C")))) -> C
A166: 46192 | B166: RIO DE JANEIRO | C166: FERRAM. TIM RJO | D166: 1000032 | E166: ALICATE DE BICO 6 | F166: PÇ | G166: 35 | H166: 8 | I166: 280 | J166: =IF(C166="","",_xlfn.XLOOKUP(UPPER(TRIM(SUBSTITUTE(SUBSTITUTE(SUBSTITUTE(TRIM(C166),"."," "),"Â","A"),"Ç","C")))&"|"&UPPER(TRIM(D166)),ABC_REF!$A:$A,ABC_REF!$B:$B,_xlfn.XLOOKUP(UPPER(TRIM(D166)),ABC_REF!$D:$D,ABC_REF!$E:$E,_xlfn.XLOOKUP(UPPER(TRIM(E166)),ABC_REF!$G:$G,ABC_REF!$H:$H,"C")))) -> A
A167: 46192 | B167: RIO DE JANEIRO | C167: FERRAM. TIM RJO | D167: 1000033 | E167: ALICATE DE CORTE 6 | F167: PÇ | G167: 35 | H167: 10 | I167: 350 | J167: =IF(C167="","",_xlfn.XLOOKUP(UPPER(TRIM(SUBSTITUTE(SUBSTITUTE(SUBSTITUTE(TRIM(C167),"."," "),"Â","A"),"Ç","C")))&"|"&UPPER(TRIM(D167)),ABC_REF!$A:$A,ABC_REF!$B:$B,_xlfn.XLOOKUP(UPPER(TRIM(D167)),ABC_REF!$D:$D,ABC_REF!$E:$E,_xlfn.XLOOKUP(UPPER(TRIM(E167)),ABC_REF!$G:$G,ABC_REF!$H:$H,"C")))) -> A
A168: 46192 | B168: RIO DE JANEIRO | C168: FERRAM. TIM RJO | D168: 1001306 | E168: ALICATE DE GRIMPAR RJ11 / RJ45 | F168: UND | G168: 30 | H168: 1 | I168: 30 | J168: =IF(C168="","",_xlfn.XLOOKUP(UPPER(TRIM(SUBSTITUTE(SUBSTITUTE(SUBSTITUTE(TRIM(C168),"."," "),"Â","A"),"Ç","C")))&"|"&UPPER(TRIM(D168)),ABC_REF!$A:$A,ABC_REF!$B:$B,_xlfn.XLOOKUP(UPPER(TRIM(D168)),ABC_REF!$D:$D,ABC_REF!$E:$E,_xlfn.XLOOKUP(UPPER(TRIM(E168)),ABC_REF!$G:$G,ABC_REF!$H:$H,"C")))) -> A
A169: 46192 | B169: RIO DE JANEIRO | C169: FERRAM. TIM RJO | D169: 1000035 | E169: ALICATE DE INSERÇÃO TERMINAL (BARGOA) | F169: UND | G169: 32.5 | H169: 14 | I169: 455 | J169: =IF(C169="","",_xlfn.XLOOKUP(UPPER(TRIM(SUBSTITUTE(SUBSTITUTE(SUBSTITUTE(TRIM(C169),"."," "),"Â","A"),"Ç","C")))&"|"&UPPER(TRIM(D169)),ABC_REF!$A:$A,ABC_REF!$B:$B,_xlfn.XLOOKUP(UPPER(TRIM(D169)),ABC_REF!$D:$D,ABC_REF!$E:$E,_xlfn.XLOOKUP(UPPER(TRIM(E169)),ABC_REF!$G:$G,ABC_REF!$H:$H,"C")))) -> A
A170: 46192 | B170: RIO DE JANEIRO | C170: FERRAM. TIM RJO | D170: 1000037 | E170: ALICATE DECAPADOR DE FIBRA OPTICA | F170: PÇ | G170: 7.1429 | H170: 16 | I170: 114.2864 | J170: =IF(C170="","",_xlfn.XLOOKUP(UPPER(TRIM(SUBSTITUTE(SUBSTITUTE(SUBSTITUTE(TRIM(C170),"."," "),"Â","A"),"Ç","C")))&"|"&UPPER(TRIM(D170)),ABC_REF!$A:$A,ABC_REF!$B:$B,_xlfn.XLOOKUP(UPPER(TRIM(D170)),ABC_REF!$D:$D,ABC_REF!$E:$E,_xlfn.XLOOKUP(UPPER(TRIM(E170)),ABC_REF!$G:$G,ABC_REF!$H:$H,"C")))) -> A
A171: 46192 | B171: RIO DE JANEIRO | C171: FERRAM. TIM RJO | D171: 1000039 | E171: ALICATE UNIVERSAL 8 | F171: PÇ | G171: 35 | H171: 12 | I171: 420 | J171: =IF(C171="","",_xlfn.XLOOKUP(UPPER(TRIM(SUBSTITUTE(SUBSTITUTE(SUBSTITUTE(TRIM(C171),"."," "),"Â","A"),"Ç","C")))&"|"&UPPER(TRIM(D171)),ABC_REF!$A:$A,ABC_REF!$B:$B,_xlfn.XLOOKUP(UPPER(TRIM(D171)),ABC_REF!$D:$D,ABC_REF!$E:$E,_xlfn.XLOOKUP(UPPER(TRIM(E171)),ABC_REF!$G:$G,ABC_REF!$H:$H,"C")))) -> A
A172: 46192 | B172: RIO DE JANEIRO | C172: FERRAM. TIM RJO | D172: 1000048 | E172: BADISCO DIGITAL GANDOLA | F172: PÇ | G172: 69.99 | H172: 10 | I172: 699.9 | J172: =IF(C172="","",_xlfn.XLOOKUP(UPPER(TRIM(SUBSTITUTE(SUBSTITUTE(SUBSTITUTE(TRIM(C172),"."," "),"Â","A"),"Ç","C")))&"|"&UPPER(TRIM(D172)),ABC_REF!$A:$A,ABC_REF!$B:$B,_xlfn.XLOOKUP(UPPER(TRIM(D172)),ABC_REF!$D:$D,ABC_REF!$E:$E,_xlfn.XLOOKUP(UPPER(TRIM(E172)),ABC_REF!$G:$G,ABC_REF!$H:$H,"C")))) -> A
A173: 46192 | B173: RIO DE JANEIRO | C173: FERRAM. TIM RJO | D173: 1000049 | E173: BALDE DE LONA | F173: PÇ | G173: 23 | H173: 6 | I173: 138 | J173: =IF(C173="","",_xlfn.XLOOKUP(UPPER(TRIM(SUBSTITUTE(SUBSTITUTE(SUBSTITUTE(TRIM(C173),"."," "),"Â","A"),"Ç","C")))&"|"&UPPER(TRIM(D173)),ABC_REF!$A:$A,ABC_REF!$B:$B,_xlfn.XLOOKUP(UPPER(TRIM(D173)),ABC_REF!$D:$D,ABC_REF!$E:$E,_xlfn.XLOOKUP(UPPER(TRIM(E173)),ABC_REF!$G:$G,ABC_REF!$H:$H,"C")))) -> A
A174: 46192 | B174: RIO DE JANEIRO | C174: FERRAM. TIM RJO | D174: 1000052 | E174: BANDEROLA DE SINALIZAÇÃO | F174: UND | G174: 10 | H174: 3 | I174: 30 | J174: =IF(C174="","",_xlfn.XLOOKUP(UPPER(TRIM(SUBSTITUTE(SUBSTITUTE(SUBSTITUTE(TRIM(C174),"."," "),"Â","A"),"Ç","C")))&"|"&UPPER(TRIM(D174)),ABC_REF!$A:$A,ABC_REF!$B:$B,_xlfn.XLOOKUP(UPPER(TRIM(D174)),ABC_REF!$D:$D,ABC_REF!$E:$E,_xlfn.XLOOKUP(UPPER(TRIM(E174)),ABC_REF!$G:$G,ABC_REF!$H:$H,"C")))) -> B
A175: 46192 | B175: RIO DE JANEIRO | C175: FERRAM. TIM RJO | D175: 1001110 | E175: BANQUETA PT ARQUPLAST | F175: PÇ | G175: 60 | H175: 5 | I175: 300 | J175: =IF(C175="","",_xlfn.XLOOKUP(UPPER(TRIM(SUBSTITUTE(SUBSTITUTE(SUBSTITUTE(TRIM(C175),"."," "),"Â","A"),"Ç","C")))&"|"&UPPER(TRIM(D175)),ABC_REF!$A:$A,ABC_REF!$B:$B,_xlfn.XLOOKUP(UPPER(TRIM(D175)),ABC_REF!$D:$D,ABC_REF!$E:$E,_xlfn.XLOOKUP(UPPER(TRIM(E175)),ABC_REF!$G:$G,ABC_REF!$H:$H,"C")))) -> B
A176: 46192 | B176: RIO DE JANEIRO | C176: FERRAM. TIM RJO | D176: 1000065 | E176: BOLSA DE LONA | F176: PÇ | G176: 35 | H176: 10 | I176: 350 | J176: =IF(C176="","",_xlfn.XLOOKUP(UPPER(TRIM(SUBSTITUTE(SUBSTITUTE(SUBSTITUTE(TRIM(C176),"."," "),"Â","A"),"Ç","C")))&"|"&UPPER(TRIM(D176)),ABC_REF!$A:$A,ABC_REF!$B:$B,_xlfn.XLOOKUP(UPPER(TRIM(D176)),ABC_REF!$D:$D,ABC_REF!$E:$E,_xlfn.XLOOKUP(UPPER(TRIM(E176)),ABC_REF!$G:$G,ABC_REF!$H:$H,"C")))) -> A
...

Sheet NITEROI
A1: Data | B1: Base | C1: Projeto | D1: Código | E1: Descrição | F1: Unidade | G1: Valor Unitario | H1: Saldo Anterior | I1: Entradas | J1: Saidas | K1: Saldo | L1: Total Real
A2: 46185 | B2: NITEROI | C2: FERRAM. NITEROI | D2: 1001663 | E2: ADAPTADOR P/ CONECTOR SC-APC (POWER METER) | F2: UN | G2: 2 | H2: 0 | I2: 132 | J2: 131 | K2: 1 | L2: 2
A3: 46185 | B3: NITEROI | C3: FERRAM. NITEROI | D3: 1000031 | E3: ALCOOL ISOPROPILICO 1000ML | F3: LT | G3: 28.9 | H3: 0 | I3: 28 | J3: 21 | K3: 7 | L3: 202.3
A4: 46185 | B4: NITEROI | C4: FERRAM. NITEROI | D4: 1001719 | E4: ALICATE COMPRESSÃO P/ CABO COAXIAL RG11 | F4: PÇ | G4: 59 | H4: 0 | I4: 136 | J4: 133 | K4: 3 | L4: 177
A5: 46185 | B5: NITEROI | C5: FERRAM. NITEROI | D5: 1000032 | E5: ALICATE DE BICO 6 | F5: PÇ | G5: 35 | H5: 0 | I5: 305 | J5: 294 | K5: 11 | L5: 385
A6: 46185 | B6: NITEROI | C6: FERRAM. NITEROI | D6: 1000033 | E6: ALICATE DE CORTE 6 | F6: PÇ | G6: 35 | H6: 0 | I6: 320 | J6: 312 | K6: 8 | L6: 280
A7: 46185 | B7: NITEROI | C7: FERRAM. NITEROI | D7: 1001306 | E7: ALICATE DE GRIMPAR RJ11 / RJ45 | F7: UND | G7: 30 | H7: 0 | I7: 288 | J7: 268 | K7: 20 | L7: 600
A8: 46185 | B8: NITEROI | C8: FERRAM. NITEROI | D8: 1000036 | E8: ALICATE DE PRESSÃO RG6 | F8: PÇ | G8: 27.99 | H8: 0 | I8: 225 | J8: 222 | K8: 3 | L8: 83.97
A9: 46185 | B9: NITEROI | C9: FERRAM. NITEROI | D9: 1000037 | E9: ALICATE DECAPADOR DE FIBRA OPTICA | F9: PÇ | G9: 7.1429 | H9: 0 | I9: 146 | J9: 134 | K9: 12 | L9: 85.7148
A10: 46185 | B10: NITEROI | C10: FERRAM. NITEROI | D10: 1000039 | E10: ALICATE UNIVERSAL 8 | F10: PÇ | G10: 35 | H10: 0 | I10: 312 | J10: 295 | K10: 17 | L10: 595
A11: 46185 | B11: NITEROI | C11: FERRAM. NITEROI | D11: 1001850 | E11: ANEL DE ANCORAGEM 1,50M | F11: PÇ | G11: 36.99 | H11: 0 | I11: 1 | J11: 0 | K11: 1 | L11: 36.99
A12: 46185 | B12: NITEROI | C12: FERRAM. NITEROI | D12: 1006180 | E12: ANEL DE ANCORAGEM 2,00 MT | F12: UN | G12: 36.99 | H12: 0 | I12: 1 | J12: 0 | K12: 1 | L12: 36.99
A13: 46185 | B13: NITEROI | C13: FERRAM. NITEROI | D13: 1001455 | E13: APLICADOR DE COLA QUENTE | F13: UN | G13: 17 | H13: 0 | I13: 285 | J13: 271 | K13: 14 | L13: 238
... A105: 46185 | B105: NITEROI | C105: FERRAM. NITEROI | D105: 1000478 | E105: VERRUMA | F105: PÇ | G105: 34 | H105: 0 | I105: 2 | J105: 1 | K105: 1 | L105: 34

Sheet LAGOS
A1: Data | B1: Base | C1: Projeto | D1: Código | E1: Descrição | F1: Unidade | G1: Valor Unitario | H1: Saldo Anterior | I1: Entradas | J1: Saidas | K1: Saldo | L1: Total Real
A2: 46185 | B2: LAGOS | C2: SEG LAGOS | D2: 1001850 | E2: ANEL DE ANCORAGEM 1,50M | F2: PÇ | G2: 36.99 | H2: 0 | I2: 48 | J2: 34 | K2: 14 | L2: 517.86
A3: 46185 | B3: LAGOS | C3: SEG LAGOS | D3: 1006180 | E3: ANEL DE ANCORAGEM 2,00 MT | F3: UN | G3: 36.99 | H3: 0 | I3: 18 | J3: 13 | K3: 5 | L3: 184.95
A4: 46185 | B4: LAGOS | C4: SEG LAGOS | D4: 1001864 | E4: BOLSA DE LONA PARA KIT LINHA DE VIDA | F4: UND | G4: 58 | H4: 0 | I4: 52 | J4: 39 | K4: 13 | L4: 754
A5: 46185 | B5: LAGOS | C5: SEG LAGOS | D5: 1000071 | E5: BOTA DE COURO SEM CADARÇO TAM. 41 | F5: PAR | G5: 54 | H5: 0 | I5: 28 | J5: 24 | K5: 4 | L5: 216
A6: 46185 | B6: LAGOS | C6: SEG LAGOS | D6: 1000072 | E6: BOTA DE COURO SEM CADARÇO TAM. 42 | F6: PAR | G6: 54 | H6: 0 | I6: 59 | J6: 56 | K6: 3 | L6: 162
A7: 46185 | B7: LAGOS | C7: SEG LAGOS | D7: 1000074 | E7: BOTA DE COURO SEM CADARÇO TAM. 44 | F7: PAR | G7: 56 | H7: 0 | I7: 6 | J7: 4 | K7: 2 | L7: 112
A8: 46185 | B8: LAGOS | C8: SEG LAGOS | D8: 1001697 | E8: CALÇA CLARO FFA CINZA - G | F8: UND | G8: 62 | H8: 0 | I8: 78 | J8: 73 | K8: 5 | L8: 310
A9: 46185 | B9: LAGOS | C9: SEG LAGOS | D9: 1001698 | E9: CALÇA CLARO FFA CINZA - GG | F9: UND | G9: 62 | H9: 0 | I9: 61 | J9: 60 | K9: 1 | L9: 62
A10: 46185 | B10: LAGOS | C10: SEG LAGOS | D10: 1006911 | E10: CALÇA DE BRIM AZUL MARINHO GIGA + TAM 40 | F10: UN | G10: 58.9 | H10: 0 | I10: 4 | J10: 1 | K10: 3 | L10: 176.7
A11: 46185 | B11: LAGOS | C11: SEG LAGOS | D11: 1006912 | E11: CALÇA DE BRIM AZUL MARINHO GIGA + TAM 42 | F11: UN | G11: 58.9 | H11: 0 | I11: 10 | J11: 0 | K11: 10 | L11: 589
A12: 46185 | B12: LAGOS | C12: SEG LAGOS | D12: 1006909 | E12: CAMISA AZUL MARINHO GIGA + TAM EXG | F12: UN | G12: 27.9 | H12: 0 | I12: 1 | J12: 0 | K12: 1 | L12: 27.9
A13: 46185 | B13: LAGOS | C13: SEG LAGOS | D13: 1006906 | E13: CAMISA AZUL MARINHO GIGA + TAM G | F13: UN | G13: 27.9 | H13: 0 | I13: 1 | J13: 0 | K13: 1 | L13: 27.9
... A45: 46185 | B45: LAGOS | C45: SEG LAGOS | D45: 1001853 | E45: TRAVA QUEDAS MOD DOBRADIÇA CORDA 12M | F45: PÇ | G45: 145 | H45: 0 | I45: 48 | J45: 34 | K45: 14 | L45: 2030
A46: 46185 | B46: LAGOS | C46: CLARO LAGOS | D46: Código | E46: Descrição | F46: Unidade | G46: Valor Unitario | H46: Saldo Anterior | I46: Entradas | J46: Saidas | K46: Saldo | L46: Total Real
A47: 46185 | B47: LAGOS | C47: CLARO LAGOS | D47: 1001663 | E47: ADAPTADOR P/ CONECTOR SC-APC (POWER METER) | F47: UN | G47: 2 | H47: 0 | I47: 116 | J47: 114 | K47: 2 | L47: 4
A48: 46185 | B48: LAGOS | C48: CLARO LAGOS | D48: 1000031 | E48: ALCOOL ISOPROPILICO 1000ML | F48: LT | G48: 28.9 | H48: 0 | I48: 1 | J48: 0 | K48: 1 | L48: 28.9
A49: 46185 | B49: LAGOS | C49: CLARO LAGOS | D49: 1000032 | E49: ALICATE DE BICO 6 | F49: PÇ | G49: 35 | H49: 0 | I49: 120 | J49: 117 | K49: 3 | L49: 105
A50: 46185 | B50: LAGOS | C50: CLARO LAGOS | D50: 1000033 | E50: ALICATE DE CORTE 6 | F50: PÇ | G50: 35 | H50: 0 | I50: 146 | J50: 142 | K50: 4 | L50: 140
A51: 46185 | B51: LAGOS | C51: CLARO LAGOS | D51: 1001306 | E51: ALICATE DE GRIMPAR RJ11 / RJ45 | F51: UND | G51: 30 | H51: 0 | I51: 90 | J51: 87 | K51: 3 | L51: 90
A52: 46185 | B52: LAGOS | C52: CLARO LAGOS | D52: 1000037 | E52: ALICATE DECAPADOR DE FIBRA OPTICA | F52: PÇ | G52: 7.1429 | H52: 0 | I52: 149 | J52: 140 | K52: 9 | L52: 64.2861
A53: 46185 | B53: LAGOS | C53: CLARO LAGOS | D53: 1000039 | E53: ALICATE UNIVERSAL 8 | F53: PÇ | G53: 35 | H53: 0 | I53: 129 | J53: 125 | K53: 4 | L53: 140
A54: 46185 | B54: LAGOS | C54: CLARO LAGOS | D54: 1001455 | E54: APLICADOR DE COLA QUENTE | F54: UN | G54: 17 | H54: 0 | I54: 83 | J54: 82 | K54: 1 | L54: 17
A55: 46185 | B55: LAGOS | C55: CLARO LAGOS | D55: 1001029 | E55: ARCO DE SERRA | F55: UND | G55: 18 | H55: 0 | I55: 5 | J55: 4 | K55: 1 | L55: 18
A56: 46185 | B56: LAGOS | C56: CLARO LAGOS | D56: 1000048 | E56: BADISCO DIGITAL GANDOLA | F56: PÇ | G56: 69.99 | H56: 0 | I56: 98 | J56: 91 | K56: 7 | L56: 489.93
A57: 46185 | B57: LAGOS | C57: CLARO LAGOS | D57: 1000049 | E57: BALDE DE LONA | F57: PÇ | G57: 23 | H57: 0 | I57: 116 | J57: 111 | K57: 5 | L57: 115
A58: 46185 | B58: LAGOS | C58: CLARO LAGOS | D58: 1000052 | E58: BANDEROLA DE SINALIZAÇÃO | F58: UND | G58: 10 | H58: 0 | I58: 27 | J58: 23 | K58: 4 | L58: 40
... A135: 46185 | B135: LAGOS | C135: CLARO LAGOS | D135: 1001461 | E135: TUBO DE COLA QUENTE | F135: UN | G135: 13.2867 | H135: 0 | I135: 9 | J135: 8 | K135: 1 | L135: 13.2867

Sheet CAMPOS
A1: Data | B1: Base | C1: Projeto | D1: Código | E1: Descrição | F1: Unidade | G1: Valor Unitario | H1: Saldo Anterior | I1: Entradas | J1: Saidas | K1: Saldo | L1: Total Real
A2: 46185 | B2: CAMPOS DOS GOYTACAZES | C2: CLARO IAT CAMPOS | D2: 1000037 | E2: ALICATE DECAPADOR DE FIBRA OPTICA | F2: PÇ | G2: 7.1429 | H2: 0 | I2: 18 | J2: 16 | K2: 2 | L2: 14.2858
A3: 46185 | B3: CAMPOS DOS GOYTACAZES | C3: CLARO IAT CAMPOS | D3: 1001488 | E3: ESCADA 5 DEGRAUS DOMESTICA | F3: UN | G3: 189 | H3: 0 | I3: 223 | J3: 221 | K3: 2 | L3: 378
A4: 46185 | B4: CAMPOS DOS GOYTACAZES | C4: SEG CAMPOS | D4: 1001850 | E4: ANEL DE ANCORAGEM 1,50M | F4: PÇ | G4: 36.99 | H4: 0 | I4: 194 | J4: 173 | K4: 21 | L4: 776.79
A5: 46185 | B5: CAMPOS DOS GOYTACAZES | C5: SEG CAMPOS | D5: 1006180 | E5: ANEL DE ANCORAGEM 2,00 MT | F5: UN | G5: 36.99 | H5: 0 | I5: 42 | J5: 30 | K5: 12 | L5: 443.88
A6: 46185 | B6: CAMPOS DOS GOYTACAZES | C6: SEG CAMPOS | D6: 1000052 | E6: BANDEROLA DE SINALIZAÇÃO | F6: UND | G6: 10 | H6: 0 | I6: 37 | J6: 14 | K6: 23 | L6: 230
A7: 46185 | B7: CAMPOS DOS GOYTACAZES | C7: SEG CAMPOS | D7: 1001864 | E7: BOLSA DE LONA PARA KIT LINHA DE VIDA | F7: UND | G7: 58 | H7: 0 | I7: 186 | J7: 170 | K7: 16 | L7: 928
A8: 46185 | B8: CAMPOS DOS GOYTACAZES | C8: SEG CAMPOS | D8: 1000068 | E8: BOTA DE COURO SEM CADARÇO TAM. 38 | F8: PAR | G8: 54 | H8: 0 | I8: 8 | J8: 7 | K8: 1 | L8: 54
A9: 46185 | B9: CAMPOS DOS GOYTACAZES | C9: SEG CAMPOS | D9: 1000070 | E9: BOTA DE COURO SEM CADARÇO TAM. 40 | F9: PAR | G9: 54 | H9: 0 | I9: 86 | J9: 73 | K9: 13 | L9: 702
A10: 46185 | B10: CAMPOS DOS GOYTACAZES | C10: SEG CAMPOS | D10: 1000071 | E10: BOTA DE COURO SEM CADARÇO TAM. 41 | F10: PAR | G10: 54 | H10: 0 | I10: 138 | J10: 128 | K10: 10 | L10: 540
A11: 46185 | B11: CAMPOS DOS GOYTACAZES | C11: SEG CAMPOS | D11: 1000072 | E11: BOTA DE COURO SEM CADARÇO TAM. 42 | F11: PAR | G11: 54 | H11: 0 | I11: 214 | J11: 207 | K11: 7 | L11: 378
A12: 46185 | B12: CAMPOS DOS GOYTACAZES | C12: SEG CAMPOS | D12: 1000073 | E12: BOTA DE COURO SEM CADARÇO TAM. 43 | F12: PAR | G12: 54 | H12: 0 | I12: 112 | J12: 91 | K12: 21 | L12: 1134
A13: 46185 | B13: CAMPOS DOS GOYTACAZES | C13: SEG CAMPOS | D13: 1000074 | E13: BOTA DE COURO SEM CADARÇO TAM. 44 | F13: PAR | G13: 56 | H13: 0 | I13: 69 | J13: 54 | K13: 15 | L13: 840
... A158: 46185 | B158: CAMPOS DOS GOYTACAZES | C158: FERRAMENTARIA CPS | D158: 1000348 | E158: MARTELO UNHA | F158: PÇ | G158: 17 | H158: 0 | I158: 145 | J158: 135 | K158: 10 | L158: 170
A159: 46185 | B159: CAMPOS DOS GOYTACAZES | C159: FERRAMENTARIA CPS | D159: 1001713 | E159: MEDIDOR DE CAMPO TRILITHIC 860 DSP | G159: 16631.64 | H159: 0 | I159: 2 | J159: 1 | K159: 1 | L159: 16631.64
A160: 46185 | B160: CAMPOS DOS GOYTACAZES | C160: FERRAMENTARIA CPS | D160: 1006121 | E160: MEDIDOR DSAM JDSU 6300 | F160: UND | G160: 5000 | H160: 0 | I160: 2 | J160: 0 | K160: 2 | L160: 10000
A161: 46185 | B161: CAMPOS DOS GOYTACAZES | C161: FERRAMENTARIA CPS | D161: 1000503 | E161: MESA DE FERRO | F161: PÇ | G161: 135 | H161: 0 | I161: 13 | J161: 10 | K161: 3 | L161: 405
A162: 46185 | B162: CAMPOS DOS GOYTACAZES | C162: FERRAMENTARIA CPS | D162: 1000363 | E162: MULTIMETRO DIGITAL | F162: PÇ | G162: 14.8 | H162: 0 | I162: 154 | J162: 147 | K162: 7 | L162: 103.6
A163: 46185 | B163: CAMPOS DOS GOYTACAZES | C163: FERRAMENTARIA CPS | D163: 1001736 | E163: ORGANIZADOR GRANDE | F163: UN | G163: 24 | H163: 0 | I163: 163 | J163: 155 | K163: 8 | L163: 192
A164: 46185 | B164: CAMPOS DOS GOYTACAZES | C164: FERRAMENTARIA CPS | D164: 1000388 | E164: PASSA FIO 20Mts ALMA DE AÇO | F164: UND | G164: 28 | H164: 0 | I164: 28 | J164: 27 | K164: 1 | L164: 28
A165: 46185 | B165: CAMPOS DOS GOYTACAZES | C165: FERRAMENTARIA CPS | D165: 1000391 | E165: PASSA FIO C/ ALMA DE AÇO 20MTS | F165: PÇ | G165: 28 | H165: 0 | I165: 79 | J165: 76 | K165: 3 | L165: 84
A166: 46185 | B166: CAMPOS DOS GOYTACAZES | C166: FERRAMENTARIA CPS | D166: 1000392 | E166: PASSA FIO NYLON (GUIA) 20MTS | F166: PÇ | G166: 29.37 | H166: 0 | I166: 67 | J166: 66 | K166: 1 | L166: 29.37
A167: 46185 | B167: CAMPOS DOS GOYTACAZES | C167: FERRAMENTARIA CPS | D167: 1000545 | E167: PILHA AA | F167: UND | G167: 0.8929 | H167: 0 | I167: 70 | J167: 60 | K167: 10 | L167: 8.929
A168: 46185 | B168: CAMPOS DOS GOYTACAZES | C168: FERRAMENTARIA CPS | D168: 1000417 | E168: POWER MEETER | F168: UND | G168: 100 | H168: 0 | I168: 44 | J168: 36 | K168: 8 | L168: 800
A169: 46185 | B169: CAMPOS DOS GOYTACAZES | C169: FERRAMENTARIA CPS | D169: 1001591 | E169: PROPE DESCARTAVEL TNT | F169: PAR | G169: 0.8 | H169: 0 | I169: 400 | J169: 0 | K169: 400 | L169: 320
A170: 46185 | B170: CAMPOS DOS GOYTACAZES | C170: FERRAMENTARIA CPS | D170: 1001669 | E170: RECIPIENTE PARA ALCOOL | F170: UN | G170: 3.5714 | H170: 0 | I170: 37 | J170: 35 | K170: 2 | L170: 7.1428
A171: 46185 | B171: CAMPOS DOS GOYTACAZES | C171: FERRAMENTARIA CPS | D171: 1001476 | E171: TESTADOR DE CABO DE REDE LAN (ETHERNET) | F171: UN | G171: 28 | H171: 0 | I171: 140 | J171: 131 | K171: 9 | L171: 252
A172: 46185 | B172: CAMPOS DOS GOYTACAZES | C172: FERRAMENTARIA CPS | D172: 1001461 | E172: TUBO DE COLA QUENTE | F172: UN | G172: 13.2867 | H172: 0 | I172: 21 | J172: 17 | K172: 4 | L172: 53.1468

Sheet PETROPOLIS
A1: Data | B1: Base | C1: Projeto | D1: Código | E1: Descrição | F1: Unidade | G1: Valor Unitario | H1: Saldo Anterior | I1: Entradas | J1: Saidas | K1: Saldo | L1: Total Real
A2: 46185 | B2: PETROPOLIS | C2: CLARO PETROPOLIS | D2: 1001663 | E2: ADAPTADOR P/ CONECTOR SC-APC (POWER METER) | F2: UN | G2: 2 | H2: 0 | I2: 32 | J2: 31 | K2: 1 | L2: 2
A3: 46185 | B3: PETROPOLIS | C3: CLARO PETROPOLIS | D3: 1000031 | E3: ALCOOL ISOPROPILICO 1000ML | F3: LT | G3: 28.9 | H3: 0 | I3: 9 | J3: 6 | K3: 3 | L3: 86.7
A4: 46185 | B4: PETROPOLIS | C4: CLARO PETROPOLIS | D4: 1001719 | E4: ALICATE COMPRESSÃO P/ CABO COAXIAL RG11 | F4: PÇ | G4: 59 | H4: 0 | I4: 32 | J4: 28 | K4: 4 | L4: 236
A5: 46185 | B5: PETROPOLIS | C5: CLARO PETROPOLIS | D5: 1000032 | E5: ALICATE DE BICO 6 | F5: PÇ | G5: 35 | H5: 0 | I5: 92 | J5: 87 | K5: 5 | L5: 175
A6: 46185 | B6: PETROPOLIS | C6: CLARO PETROPOLIS | D6: 1000033 | E6: ALICATE DE CORTE 6 | F6: PÇ | G6: 35 | H6: 0 | I6: 85 | J6: 81 | K6: 4 | L6: 140
A7: 46185 | B7: PETROPOLIS | C7: CLARO PETROPOLIS | D7: 1001306 | E7: ALICATE DE GRIMPAR RJ11 / RJ45 | F7: UND | G7: 30 | H7: 0 | I7: 99 | J7: 91 | K7: 8 | L7: 240
A8: 46185 | B8: PETROPOLIS | C8: CLARO PETROPOLIS | D8: 1000036 | E8: ALICATE DE PRESSÃO RG6 | F8: PÇ | G8: 27.99 | H8: 0 | I8: 47 | J8: 41 | K8: 6 | L8: 167.94
A9: 46185 | B9: PETROPOLIS | C9: CLARO PETROPOLIS | D9: 1000037 | E9: ALICATE DECAPADOR DE FIBRA OPTICA | F9: PÇ | G9: 7.1429 | H9: 0 | I9: 64 | J9: 61 | K9: 3 | L9: 21.4287
A10: 46185 | B10: PETROPOLIS | C10: CLARO PETROPOLIS | D10: 1000039 | E10: ALICATE UNIVERSAL 8 | F10: PÇ | G10: 35 | H10: 0 | I10: 91 | J10: 84 | K10: 7 | L10: 245
A11: 46185 | B11: PETROPOLIS | C11: CLARO PETROPOLIS | D11: 1001455 | E11: APLICADOR DE COLA QUENTE | F11: UN | G11: 17 | H11: 0 | I11: 83 | J11: 80 | K11: 3 | L11: 51
A12: 46185 | B12: PETROPOLIS | C12: CLARO PETROPOLIS | D12: 1000048 | E12: BADISCO DIGITAL GANDOLA | F12: PÇ | G12: 69.99 | H12: 0 | I12: 76 | J12: 74 | K12: 2 | L12: 139.98
A13: 46185 | B13: PETROPOLIS | C13: CLARO PETROPOLIS | D13: 1000049 | E13: BALDE DE LONA | F13: PÇ | G13: 23 | H13: 0 | I13: 82 | J13: 81 | K13: 1 | L13: 23
... A129: 46185 | B129: PETROPOLIS | C129: SEG PETROPOLIS | D129: 1001853 | E129: TRAVA QUEDAS MOD DOBRADIÇA CORDA 12M | F129: PÇ | G129: 145 | H129: 0 | I129: 69 | J129: 64 | K129: 5 | L129: 725

Sheet TERESOPOLIS
A1: Data | B1: Base | C1: Projeto | D1: Código | E1: Descrição | F1: Unidade | G1: Valor Unitario | H1: Saldo Anterior | I1: Entradas | J1: Saidas | K1: Saldo | L1: Total Real
A2: 46185 | B2: TERESOPOLIS | C2: SEG TERESOPOLIS | D2: 1001850 | E2: ANEL DE ANCORAGEM 1,50M | F2: PÇ | G2: 36.99 | H2: 0 | I2: 23 | J2: 22 | K2: 1 | L2: 36.99
A3: 46185 | B3: TERESOPOLIS | C3: SEG TERESOPOLIS | D3: 1000052 | E3: BANDEROLA DE SINALIZAÇÃO | F3: UND | G3: 10 | H3: 0 | I3: 10 | J3: 9 | K3: 1 | L3: 10
A4: 46185 | B4: TERESOPOLIS | C4: SEG TERESOPOLIS | D4: 1001864 | E4: BOLSA DE LONA PARA KIT LINHA DE VIDA | F4: UND | G4: 58 | H4: 0 | I4: 21 | J4: 18 | K4: 3 | L4: 174
A5: 46185 | B5: TERESOPOLIS | C5: SEG TERESOPOLIS | D5: 1001973 | E5: CAMISA MALHA PV AZUL ROYAL M | F5: UN | G5: 25 | H5: 0 | I5: 2 | J5: 0 | K5: 2 | L5: 50
A6: 46185 | B6: TERESOPOLIS | C6: SEG TERESOPOLIS | D6: 1001694 | E6: CAMISA POLO CINZA - CLARO FFA - GG | F6: UND | G6: 48 | H6: 0 | I6: 13 | J6: 12 | K6: 1 | L6: 48
A7: 46185 | B7: TERESOPOLIS | C7: SEG TERESOPOLIS | D7: 1001289 | E7: CANETA DETECTORA DE TENSÃO 90 - 1000V | F7: UND | G7: 17 | H7: 0 | I7: 25 | J7: 20 | K7: 5 | L7: 85
A8: 46185 | B8: TERESOPOLIS | C8: SEG TERESOPOLIS | D8: 1001190 | E8: CAPACETE ABA TOTAL AZESC | F8: PÇ | G8: 34 | H8: 0 | I8: 24 | J8: 22 | K8: 2 | L8: 68
A9: 46185 | B9: TERESOPOLIS | C9: SEG TERESOPOLIS | D9: 1000146 | E9: CARNEIRA P/CAPACETE | F9: PÇ | G9: 9 | H9: 0 | I9: 21 | J9: 19 | K9: 2 | L9: 18
A10: 46185 | B10: TERESOPOLIS | C10: SEG TERESOPOLIS | D10: 1000204 | E10: CINTO SEG. PQD C/3 PONTAS E PROT. LOMBAR-APASEG | F10: PÇ | G10: 140 | H10: 0 | I10: 21 | J10: 20 | K10: 1 | L10: 140
A11: 46185 | B11: TERESOPOLIS | C11: SEG TERESOPOLIS | D11: 1002341 | E11: CINTO SEG. PQD C/3 PONTAS E PROT. LOMBAR -TAM 02 | F11: UN | G11: 85 | H11: 0 | I11: 2 | J11: 1 | K11: 1 | L11: 85
A12: 46185 | B12: TERESOPOLIS | C12: SEG TERESOPOLIS | D12: 1000208 | E12: CONE SINALIZAÇÃO GRANDE | F12: UND | G12: 29 | H12: 0 | I12: 27 | J12: 24 | K12: 3 | L12: 87
A13: 46185 | B13: TERESOPOLIS | C13: SEG TERESOPOLIS | D13: 1001854 | E13: CORDA TRANC 12 MM LVM 20M | F13: PÇ | G13: 90 | H13: 0 | I13: 16 | J13: 15 | K13: 1 | L13: 90
... A74: 46185 | B74: TERESOPOLIS | C74: CLARO TERESOPOLIS | D74: 1001476 | E74: TESTADOR DE CABO DE REDE LAN (ETHERNET) | F74: UN | G74: 28 | H74: 0 | I74: 45 | J74: 43 | K74: 2 | L74: 56

Sheet NOVA FRIBURGO
A1: Data | B1: Base | C1: Projeto | D1: Código | E1: Descrição | F1: Unidade | G1: Valor Unitario | H1: Saldo Anterior | I1: Entradas | J1: Saidas | K1: Saldo | L1: Total Real
A2: 46185 | B2: NOVA FRIBURGO | C2: FERRAM. CLARO IAT | D2: 1001663 | E2: ADAPTADOR P/ CONECTOR SC-APC (POWER METER) | F2: UN | G2: 2 | H2: 0 | I2: 66 | J2: 55 | K2: 11 | L2: 22
A3: 46185 | B3: NOVA FRIBURGO | C3: FERRAM. CLARO IAT | D3: 1000032 | E3: ALICATE DE BICO 6 | F3: PÇ | G3: 35 | H3: 0 | I3: 116 | J3: 107 | K3: 9 | L3: 315
A4: 46185 | B4: NOVA FRIBURGO | C4: FERRAM. CLARO IAT | D4: 1000033 | E4: ALICATE DE CORTE 6 | F4: PÇ | G4: 35 | H4: 0 | I4: 132 | J4: 129 | K4: 3 | L4: 105
A5: 46185 | B5: NOVA FRIBURGO | C5: FERRAM. CLARO IAT | D5: 1001306 | E5: ALICATE DE GRIMPAR RJ11 / RJ45 | F5: UND | G5: 30 | H5: 0 | I5: 52 | J5: 48 | K5: 4 | L5: 120
A6: 46185 | B6: NOVA FRIBURGO | C6: FERRAM. CLARO IAT | D6: 1000037 | E6: ALICATE DECAPADOR DE FIBRA OPTICA | F6: PÇ | G6: 7.1429 | H6: 0 | I6: 88 | J6: 85 | K6: 3 | L6: 21.4287
A7: 46185 | B7: NOVA FRIBURGO | C7: FERRAM. CLARO IAT | D7: 1000039 | E7: ALICATE UNIVERSAL 8 | F7: PÇ | G7: 35 | H7: 0 | I7: 78 | J7: 67 | K7: 11 | L7: 385
A8: 46185 | B8: NOVA FRIBURGO | C8: FERRAM. CLARO IAT | D8: 1001455 | E8: APLICADOR DE COLA QUENTE | F8: UN | G8: 17 | H8: 0 | I8: 78 | J8: 73 | K8: 5 | L8: 85
A9: 46185 | B9: NOVA FRIBURGO | C9: FERRAM. CLARO IAT | D9: 1000048 | E9: BADISCO DIGITAL GANDOLA | F9: PÇ | G9: 69.99 | H9: 0 | I9: 95 | J9: 90 | K9: 5 | L9: 349.95
A10: 46185 | B10: NOVA FRIBURGO | C10: FERRAM. CLARO IAT | D10: 1000049 | E10: BALDE DE LONA | F10: PÇ | G10: 23 | H10: 0 | I10: 93 | J10: 87 | K10: 6 | L10: 138
A11: 46185 | B11: NOVA FRIBURGO | C11: FERRAM. CLARO IAT | D11: 1000060 | E11: BATERIA 9 V | F11: PÇ | G11: 7.5 | H11: 0 | I11: 14 | J11: 2 | K11: 12 | L11: 90
A12: 46185 | B12: NOVA FRIBURGO | C12: FERRAM. CLARO IAT | D12: 1000065 | E12: BOLSA DE LONA | F12: PÇ | G12: 35 | H12: 0 | I12: 101 | J12: 91 | K12: 10 | L12: 350
A13: 46185 | B13: NOVA FRIBURGO | C13: FERRAM. CLARO IAT | D13: 1000082 | E13: BROCA 5/16 X 8 WIDIA | F13: UND | G13: 3.9 | H13: 0 | I13: 1 | J13: 0 | K13: 1 | L13: 3.9
... A106: 46185 | B106: NOVA FRIBURGO | C106: SEG NOVA FRIBURGO | D106: 1001853 | E106: TRAVA QUEDAS MOD DOBRADIÇA CORDA 12M | F106: PÇ | G106: 145 | H106: 0 | I106: 28 | J106: 24 | K106: 4 | L106: 580

Sheet OLARIA
A1: Data | B1: Base | C1: Projeto | D1: Código | E1: Descrição | F1: Unidade | G1: Valor Unitario | H1: Saldo Anterior | I1: Entradas | J1: Saidas | K1: Saldo | L1: Total Real
A2: 46192 | B2: OLARIA | C2: FERRAM. REG. RJ | D2: 1001663 | E2: ADAPTADOR P/ CONECTOR SC-APC (POWER METER) | F2: UN | G2: 2 | H2: 0 | I2: 577 | J2: 459 | K2: 118 | L2: 236
A3: 46192 | B3: OLARIA | C3: FERRAM. REG. RJ | D3: 1000021 | E3: ALAVANCA DE AÇO 1,45MTS | F3: PÇ | G3: 142 | H3: 0 | I3: 15 | J3: 0 | K3: 15 | L3: 2130
A4: 46192 | B4: OLARIA | C4: FERRAM. REG. RJ | D4: 1002304 | E4: ALCOOL ISOPROPILICO LT | F4: LT | G4: 22.9 | H4: 0 | I4: 35 | J4: 0 | K4: 35 | L4: 801.5
A5: 46192 | B5: OLARIA | C5: FERRAM. REG. RJ | D5: 1000031 | E5: ALCOOL ISOPROPILICO 1000ML | F5: LT | G5: 28.9 | H5: 0 | I5: 55 | J5: 35 | K5: 20 | L5: 578
A6: 46192 | B6: OLARIA | C6: FERRAM. REG. RJ | D6: 1001915 | E6: ALCOOL ISOPROPILICO 250ML | F6: UN | G6: 24.21 | H6: 0 | I6: 5 | J6: 0 | K6: 5 | L6: 121.05
A7: 46192 | B7: OLARIA | C7: FERRAM. REG. RJ | D7: 1001268 | E7: ALICATE AMPERÍMETRO | F7: UND | G7: 67 | H7: 0 | I7: 6 | J7: 5 | K7: 1 | L7: 67
A8: 46192 | B8: OLARIA | C8: FERRAM. REG. RJ | D8: 1001719 | E8: ALICATE COMPRESSÃO P/ CABO COAXIAL RG11 | F8: PÇ | G8: 59 | H8: 0 | I8: 288 | J8: 254 | K8: 34 | L8: 2006
A9: 46192 | B9: OLARIA | C9: FERRAM. REG. RJ | D9: 1001962 | E9: ALICATE CORTA E DESENCAPA CABO (BANANA) | F9: UNID | G9: 75 | H9: 0 | I9: 12 | J9: 10 | K9: 2 | L9: 150
A10: 46192 | B10: OLARIA | C10: FERRAM. REG. RJ | D10: 1000032 | E10: ALICATE DE BICO 6 | F10: PÇ | G10: 35 | H10: 0 | I10: 830 | J10: 740 | K10: 90 | L10: 3150
A11: 46192 | B11: OLARIA | C11: FERRAM. REG. RJ | D11: 1000033 | E11: ALICATE DE CORTE 6 | F11: PÇ | G11: 35 | H11: 0 | I11: 825 | J11: 811 | K11: 14 | L11: 490
A12: 46192 | B12: OLARIA | C12: FERRAM. REG. RJ | D12: 1001306 | E12: ALICATE DE GRIMPAR RJ11 / RJ45 | F12: UND | G12: 30 | H12: 0 | I12: 401 | J12: 353 | K12: 48 | L12: 1440
A13: 46192 | B13: OLARIA | C13: FERRAM. REG. RJ | D13: 1000035 | E13: ALICATE DE INSERÇÃO TERMINAL (BARGOA) | F13: UND | G13: 32.5 | H13: 0 | I13: 331 | J13: 160 | K13: 171 | L13: 5557.5
... A36: 46192 | B36: OLARIA | C36: FERRAM. REG. RJ | D36: 1002051 | E36: BOBINA PICOTADA 40X60 | F36: UN | G36: 52.05 | H36: 0 | I36: 37 | J36: 21 | K36: 16 | L36: 832.8
A37: 46192 | B37: OLARIA | C37: FERRAM. REG. RJ | D37: 1002151 | E37: BOCAL | G37: 1.8 | H37: 0 | I37: 51 | J37: 22 | K37: 29 | L37: 52.2
A38: 46192 | B38: OLARIA | C38: FERRAM. REG. RJ | D38: 1000065 | E38: BOLSA DE LONA | F38: PÇ | G38: 35 | H38: 0 | I38: 740 | J38: 668 | K38: 72 | L38: 2520
A39: 46192 | B39: OLARIA | C39: FERRAM. REG. RJ | D39: 1008891 | E39: BROCA 3 PONTAS P/ MADEIRA 10MM | F39: PÇ | G39: 12 | H39: 0 | I39: 78 | J39: 12 | K39: 66 | L39: 792
A40: 46192 | B40: OLARIA | C40: FERRAM. REG. RJ | D40: 1001986 | E40: BROCA 3 PONTAS P/ MADEIRA 8MM | F40: UN | G40: 17.3333 | H40: 0 | I40: 55 | J40: 13 | K40: 42 | L40: 727.9986
A41: 46192 | B41: OLARIA | C41: FERRAM. REG. RJ | D41: 1002284 | E41: BROCA AÇO RAPIDO 4MM | F41: UN | G41: 1.9 | H41: 0 | I41: 58 | J41: 21 | K41: 37 | L41: 70.3
A42: 46192 | B42: OLARIA | C42: FERRAM. REG. RJ | D42: 1001456 | E42: BROCA AÇO RAPIDO 6MM | F42: UN | G42: 2.9 | H42: 0 | I42: 96 | J42: 75 | K42: 21 | L42: 60.9
A43: 46192 | B43: OLARIA | C43: FERRAM. REG. RJ | D43: 1002244 | E43: BROCA AÇO RAPIDO 8MM | F43: UN | G43: 8 | H43: 0 | I43: 16 | J43: 7 | K43: 9 | L43: 72
A44: 46192 | B44: OLARIA | C44: FERRAM. REG. RJ | D44: 1001712 | E44: BROCA CHATA MADEIRA 6MM X 150MM | F44: UN | G44: 11 | H44: 0 | I44: 195 | J44: 145 | K44: 50 | L44: 550
A45: 46192 | B45: OLARIA | C45: FERRAM. REG. RJ | D45: 1001702 | E45: BROCA CHATA MADEIRA 10 MM X 150 MM | F45: UN | G45: 12 | H45: 0 | I45: 218 | J45: 193 | K45: 25 | L45: 300
A46: 46192 | B46: OLARIA | C46: FERRAM. REG. RJ | D46: 1001701 | E46: BROCA CHATA MADEIRA 8 MM X 150 MM | F46: UN | G46: 13 | H46: 0 | I46: 213 | J46: 181 | K46: 32 | L46: 416
A47: 46192 | B47: OLARIA | C47: FERRAM. REG. RJ | D47: 1001686 | E47: BROCA DE AÇO RÁPIDO 8MM | F47: UND | G47: 8 | H47: 0 | I47: 80 | J47: 19 | K47: 61 | L47: 488
A48: 46192 | B48: OLARIA | C48: FERRAM. REG. RJ | D48: 1001680 | E48: BROCA DE WIDEA 10MM X 400MM ( LONGA) | F48: PÇ | G48: 14.9 | H48: 0 | I48: 622 | J48: 561 | K48: 61 | L48: 908.9
A49: 46192 | B49: OLARIA | C49: FERRAM. REG. RJ | D49: 1001941 | E49: BROCA DE WIDEA 8MM X 400MM (LONGA) | F49: UNID | G49: 3.8 | H49: 0 | I49: 424 | J49: 291 | K49: 133 | L49: 505.4
... A164: 46192 | B164: OLARIA | C164: FERRAM. REG. RJ | D164: 1002270 | E164: FURADEIRA HAMMER 700W | F164: UN | G164: 140 | H164: 0 | I164: 191 | J164: 160 | K164: 31 | L164: 4340
A165: 46192 | B165: OLARIA | C165: FERRAM. REG. RJ | D165: 1001940 | E165: FURADEIRA SKIL MODELO 6662 550W 127V | F165: UND | G165: 227.3 | H165: 0 | I165: 38 | J165: 37 | K165: 1
A166: 46192 | B166: OLARIA | C166: FERRAM. TIM RJO | D166: 1000032 | E166: ALICATE DE BICO 6 | F166: PÇ | G166: 35 | H166: 0 | I166: 1607 | J166: 1599 | K166: 8 | L166: 280
A167: 46192 | B167: OLARIA | C167: FERRAM. TIM RJO | D167: 1000033 | E167: ALICATE DE CORTE 6 | F167: PÇ | G167: 35 | H167: 0 | I167: 1750 | J167: 1740 | K167: 10 | L167: 350
A168: 46192 | B168: OLARIA | C168: FERRAM. TIM RJO | D168: 1001306 | E168: ALICATE DE GRIMPAR RJ11 / RJ45 | F168: UND | G168: 30 | H168: 0 | I168: 129 | J168: 128 | K168: 1 | L168: 30
A169: 46192 | B169: OLARIA | C169: FERRAM. TIM RJO | D169: 1000035 | E169: ALICATE DE INSERÇÃO TERMINAL (BARGOA) | F169: UND | G169: 32.5 | H169: 0 | I169: 1068 | J169: 1054 | K169: 14 | L169: 455
A170: 46192 | B170: OLARIA | C170: FERRAM. TIM RJO | D170: 1000037 | E170: ALICATE DECAPADOR DE FIBRA OPTICA | F170: PÇ | G170: 7.1429 | H170: 0 | I170: 1983 | J170: 1967 | K170: 16 | L170: 114.2864
A171: 46192 | B171: OLARIA | C171: FERRAM. TIM RJO | D171: 1000039 | E171: ALICATE UNIVERSAL 8 | F171: PÇ | G171: 35 | H171: 0 | I171: 1529 | J171: 1517 | K171: 12 | L171: 420
A172: 46192 | B172: OLARIA | C172: FERRAM. TIM RJO | D172: 1000048 | E172: BADISCO DIGITAL GANDOLA | F172: PÇ | G172: 69.99 | H172: 0 | I172: 1161 | J172: 1151 | K172: 10 | L172: 699.9
A173: 46192 | B173: OLARIA | C173: FERRAM. TIM RJO | D173: 1000049 | E173: BALDE DE LONA | F173: PÇ | G173: 23 | H173: 0 | I173: 1551 | J173: 1545 | K173: 6 | L173: 138
A174: 46192 | B174: OLARIA | C174: FERRAM. TIM RJO | D174: 1000052 | E174: BANDEROLA DE SINALIZAÇÃO | F174: UND | G174: 10 | H174: 0 | I174: 1031 | J174: 1028 | K174: 3 | L174: 30
A175: 46192 | B175: OLARIA | C175: FERRAM. TIM RJO | D175: 1001110 | E175: BANQUETA PT ARQUPLAST | F175: PÇ | G175: 60 | H175: 0 | I175: 268 | J175: 263 | K175: 5 | L175: 300
A176: 46192 | B176: OLARIA | C176: FERRAM. TIM RJO | D176: 1000065 | E176: BOLSA DE LONA | F176: PÇ | G176: 35 | H176: 0 | I176: 1428 | J176: 1418 | K176: 10 | L176: 350
...

Sheet UBERLANDIA
A1: Data | B1: BASE | C1: Projeto | D1: Código | E1: Descrição | F1: Unidade | G1: Valor Unitario | H1: Saldo Anterior | I1: Entradas | J1: Saidas | K1: Saldo | L1: Total Real
A2: 46192 | B2: UBERLANDIA | C2: FERRAM. UBERLÂNDIA | D2: 1006884 | E2: ALFABETO CHAPA VAZADA 25MM | F2: UN | G2: 15.6747 | H2: 0 | I2: 1 | J2: 0 | K2: 1 | L2: 15.6747
A3: 46192 | B3: UBERLANDIA | C3: FERRAM. UBERLÂNDIA | D3: 1006882 | E3: ALFABETO DE BATER 5MM | F3: UN | G3: 54.2 | H3: 0 | I3: 1 | J3: 0 | K3: 1 | L3: 54.2
A4: 46192 | B4: UBERLANDIA | C4: FERRAM. UBERLÂNDIA | D4: 1006885 | E4: ALGARISMO CHAPA VAZADA | F4: UN | G4: 15.6753 | H4: 0 | I4: 1 | J4: 0 | K4: 1 | L4: 15.6753
A5: 46192 | B5: UBERLANDIA | C5: FERRAM. UBERLÂNDIA | D5: 1006883 | E5: ALGARISMO DE BATER 5MM | F5: UN | G5: 19.7 | H5: 0 | I5: 1 | J5: 0 | K5: 1 | L5: 19.7
A6: 46192 | B6: UBERLANDIA | C6: FERRAM. UBERLÂNDIA | D6: 1006890 | E6: CHAVE BAP 14mm | F6: PÇ | G6: 49.99 | H6: 0 | I6: 2 | J6: 1 | K6: 1 | L6: 49.99
A7: 46192 | B7: UBERLANDIA | C7: FERRAM. UBERLÂNDIA | D7: 100120 | E7: CHAVE BOCA/ESTRIA 13MM | F7: UN | G7: 12.99 | H7: 0 | I7: 1 | J7: 0 | K7: 1 | L7: 12.99
A8: 46192 | B8: UBERLANDIA | C8: FERRAM. UBERLÂNDIA | D8: 1002103 | E8: CHAVE CANHAO 1/8 | F8: PÇ | G8: 23.95 | H8: 0 | I8: 12 | J8: 8 | K8: 4 | L8: 95.8
A9: 46192 | B9: UBERLANDIA | C9: FERRAM. UBERLÂNDIA | D9: 1006950 | E9: CHAVE CANHAO 5MM | F9: UN | G9: 12.37 | H9: 0 | I9: 2 | J9: 0 | K9: 2 | L9: 24.74
A10: 46192 | B10: UBERLANDIA | C10: FERRAM. UBERLÂNDIA | D10: 1006952 | E10: CHAVE COMBINADA 23MM | F10: UN | G10: 18.7 | H10: 0 | I10: 1 | J10: 0 | K10: 1 | L10: 18.7
A11: 46192 | B11: UBERLANDIA | C11: FERRAM. UBERLÂNDIA | D11: 1006951 | E11: CHAVE COMBINADA 27MM | F11: UN | G11: 37.85 | H11: 0 | I11: 2 | J11: 1 | K11: 1 | L11: 37.85
A12: 46192 | B12: UBERLANDIA | C12: FERRAM. UBERLÂNDIA | D12: 1006844 | E12: CHAVE DE FENDA 1/8 | F12: PÇ | G12: 2.9 | H12: 0 | I12: 44 | J12: 39 | K12: 5 | L12: 14.5
A13: 46192 | B13: UBERLANDIA | C13: FERRAM. UBERLÂNDIA | D13: 1008917 | E13: EXTENSÃO 30 MTS | F13: UN | G13: 67.85 | H13: 0 | I13: 1 | J13: 0 | K13: 1 | L13: 67.85
... A78: 46192 | B78: UBERLANDIA | C78: SSO UBERLÂNDIA | D78: 1000995 | E78: TALABARTE DE POSICIONAMENTO REGULÁVEL-(APA SEG). | F78: UND | G78: 170 | H78: 0 | I78: 39 | J78: 38 | K78: 1 | L78: 170

Sheet GOVERNADOR VALADARES
A1: Data | B1: Cidade | C1: Projeto | D1: Código | E1: Descrição | F1: Unidade | G1: Valor Unitario | H1: Saldo Anterior | I1: Entradas | J1: Saidas | K1: Saldo | L1: Total Real
A2: 46192 | B2: VALADARES | C2: FFA GOV VALADARES | D2: 1002163 | E2: CURVA AÇO GALVANIZADO PESADO 11/2" X 90º | F2: UN | G2: 23 | H2: 0 | I2: 24 | J2: 0 | K2: 24 | L2: 552
A3: 46192 | B3: VALADARES | C3: FFA GOV VALADARES | D3: 1002162 | E3: ELETRODUTO AÇO GALV. A FOGO PESADO 11/2" X 3M | F3: UN | G3: 130 | H3: 0 | I3: 21 | J3: 0 | K3: 21 | L3: 2730
A4: 46192 | B4: VALADARES | C4: FFA GOV VALADARES | D4: 1002164 | E4: LUVA AÇO GALVANIZADO PESADO 11/2" | F4: UN | G4: 12 | H4: 0 | I4: 6 | J4: 0 | K4: 6 | L4: 72
A5: 46192 | B5: VALADARES | C5: FFA GOV VALADARES | D5: 1006889 | E5: TINTA ESMALTE AMARELA 900ML | F5: UN | G5: 32 | H5: 0 | I5: 1 | J5: 0 | K5: 1 | L5: 32
A6: 46192 | B6: VALADARES | C6: FFA GOV VALADARES | D6: 1006872 | E6: TINTA ESMALTE AZUL 900ML | F6: PÇ | G6: 42.6 | H6: 0 | I6: 1 | J6: 0 | K6: 1 | L6: 42.6
A7: 46192 | B7: VALADARES | C7: FFA GOV VALADARES | D7: 1006888 | E7: TINTA ESMALTE PRETA 900ML | F7: UN | G7: 32 | H7: 0 | I7: 1 | J7: 0 | K7: 1 | L7: 32
A8: 46192 | B8: VALADARES | C8: FERRAMENTAL GOV VALA | D8: 1006835 | E8: CHAVE BOCA/ESTRIA 3/8 | F8: PÇ | G8: 9.85 | H8: 0 | I8: 31 | J8: 30 | K8: 1 | L8: 9.85
A9: 46192 | B9: VALADARES | C9: FERRAMENTAL GOV VALA | D9: 1006836 | E9: CHAVE BOCA/ESTRIA 5/16 | F9: PÇ | G9: 10.2 | H9: 0 | I9: 31 | J9: 30 | K9: 1 | L9: 10.2
A10: 46192 | B10: VALADARES | C10: FERRAMENTAL GOV VALA | D10: 1006827 | E10: CHAVE CANHAO 1/2 | F10: PÇ | G10: 19.99 | H10: 0 | I10: 41 | J10: 38 | K10: 3 | L10: 59.97
A11: 46192 | B11: VALADARES | C11: FERRAMENTAL GOV VALA | D11: 1006828 | E11: CHAVE CANHAO 1/4 | F11: PÇ | G11: 10.45 | H11: 0 | I11: 42 | J11: 39 | K11: 3 | L11: 31.35
A12: 46192 | B12: VALADARES | C12: FERRAMENTAL GOV VALA | D12: 1006829 | E12: CHAVE CANHAO 3/16 | F12: PÇ | G12: 10.25 | H12: 0 | I12: 45 | J12: 40 | K12: 5 | L12: 51.25
A13: 46192 | B13: VALADARES | C13: FERRAMENTAL GOV VALA | D13: 1006832 | E13: CHAVE CANHAO 7/32 | F13: PÇ | G13: 8.5 | H13: 0 | I13: 43 | J13: 41 | K13: 2 | L13: 17
... A76: 46192 | B76: VALADARES | C76: SSO GOV. VALADARES | D76: 1001853 | E76: TRAVA QUEDAS MOD DOBRADIÇA CORDA 12M | F76: PÇ | G76: 145 | H76: 0 | I76: 46 | J76: 44 | K76: 2 | L76: 290

Sheet BELO HORIZONTE
A1: Data | B1: Base | C1: Projeto | D1: Código | E1: Descrição | F1: Unidade | G1: Valor Unitario | H1: Saldo Anterior | I1: Entradas | J1: Saidas | K1: Saldo | L1: Total Real
A2: 46192 | B2: BELO HORIZONTE | C2: SSO BELO HORIZONTE | D2: 1001850 | E2: ANEL DE ANCORAGEM 1,50M | F2: PÇ | G2: 36.99 | H2: 0 | I2: 366 | J2: 321 | K2: 45 | L2: 1664.55
A3: 46192 | B3: BELO HORIZONTE | C3: SSO BELO HORIZONTE | D3: 1006180 | E3: ANEL DE ANCORAGEM 2,00 MT | F3: UN | G3: 36.99 | H3: 0 | I3: 353 | J3: 319 | K3: 34 | L3: 1257.66
A4: 46192 | B4: BELO HORIZONTE | C4: SSO BELO HORIZONTE | D4: 1000052 | E4: BANDEROLA DE SINALIZAÇÃO | F4: UND | G4: 10 | H4: 0 | I4: 279 | J4: 265 | K4: 14 | L4: 140
A5: 46192 | B5: BELO HORIZONTE | C5: SSO BELO HORIZONTE | D5: 1000657 | E5: BARRACA TENDA GAZEBO | F5: PÇ | G5: 380 | H5: 0 | I5: 7 | J5: 0 | K5: 7 | L5: 2660
A6: 46192 | B6: BELO HORIZONTE | C6: SSO BELO HORIZONTE | D6: 1001864 | E6: BOLSA DE LONA PARA KIT LINHA DE VIDA | F6: UND | G6: 58 | H6: 0 | I6: 437 | J6: 403 | K6: 34 | L6: 1972
A7: 46192 | B7: BELO HORIZONTE | C7: SSO BELO HORIZONTE | D7: 1001521 | E7: BOTA BORRACHA PVC 38 | F7: un | G7: 33.98 | H7: 0 | I7: 1 | J7: 0 | K7: 1 | L7: 33.98
A8: 46192 | B8: BELO HORIZONTE | C8: SSO BELO HORIZONTE | D8: 1001523 | E8: BOTA BORRACHA PVC 40 | F8: un | G8: 33.98 | H8: 0 | I8: 9 | J8: 8 | K8: 1 | L8: 33.98
A9: 46192 | B9: BELO HORIZONTE | C9: SSO BELO HORIZONTE | D9: 1001524 | E9: BOTA BORRACHA PVC 41 | F9: un | G9: 54 | H9: 0 | I9: 12 | J9: 3 | K9: 9 | L9: 486
A10: 46192 | B10: BELO HORIZONTE | C10: SSO BELO HORIZONTE | D10: 1001525 | E10: BOTA BORRACHA PVC 42 | F10: un | G10: 54 | H10: 0 | I10: 23 | J10: 14 | K10: 9 | L10: 486
A11: 46192 | B11: BELO HORIZONTE | C11: SSO BELO HORIZONTE | D11: 1001526 | E11: BOTA BORRACHA PVC 43 | F11: un | G11: 54 | H11: 0 | I11: 9 | J11: 6 | K11: 3 | L11: 162
A12: 46192 | B12: BELO HORIZONTE | C12: SSO BELO HORIZONTE | D12: 1001249 | E12: BOTA DE COURO SEM CADARÇO TAM. 37 | F12: PAR | G12: 45 | H12: 0 | I12: 7 | J12: 3 | K12: 4 | L12: 180
A13: 46192 | B13: BELO HORIZONTE | C13: SSO BELO HORIZONTE | D13: 1000068 | E13: BOTA DE COURO SEM CADARÇO TAM. 38 | F13: PAR | G13: 54 | H13: 0 | I13: 62 | J13: 52 | K13: 10 | L13: 540
... A77: 46192 | B77: BELO HORIZONTE | C77: SSO BELO HORIZONTE | D77: 1000544 | E77: MOSQUETAO DE FERRO | F77: UND | G77: 39 | H77: 0 | I77: 168 | J77: 129 | K77: 39 | L77: 1521
A78: 46192 | B78: BELO HORIZONTE | C78: SSO BELO HORIZONTE | D78: 1001562 | E78: NIVELADOR ESCADA DE MADEIRA | F78: UN | G78: 58 | H78: 0 | I78: 381 | J78: 368
A79: 46192 | B79: BELO HORIZONTE | C79: FFA BELO HORIZONTE | D79: 60000570 | E79: CABO FIBRA OPTICA SM AS120 S 72 RC | F79: M | G79: 4.2986 | H79: 0 | I79: 6221 | J79: 5922 | K79: 299 | L79: 1285.2814
A80: 46192 | B80: BELO HORIZONTE | C80: FFA BELO HORIZONTE | D80: 1002163 | E80: CURVA AÇO GALVANIZADO PESADO 11/2" X 90º | F80: UN | G80: 23 | H80: 0 | I80: 81 | J80: 41 | K80: 40 | L80: 920
A81: 46192 | B81: BELO HORIZONTE | C81: FFA BELO HORIZONTE | D81: 1002162 | E81: ELETRODUTO AÇO GALV. A FOGO PESADO 11/2" X 3M | F81: UN | G81: 130 | H81: 0 | I81: 160 | J81: 93 | K81: 67 | L81: 8710
A82: 46192 | B82: BELO HORIZONTE | C82: FFA BELO HORIZONTE | D82: 1002164 | E82: LUVA AÇO GALVANIZADO PESADO 11/2" | F82: UN | G82: 12 | H82: 0 | I82: 110 | J82: 26 | K82: 84 | L82: 1008
A83: 46192 | B83: BELO HORIZONTE | C83: FFA BELO HORIZONTE | D83: 1008914 | E83: LUVA COMPRESSAO DE PP DN40MM X DN40MM | F83: UN | G83: 10 | H83: 0 | I83: 10 | J83: 0 | K83: 10 | L83: 100
A84: 46192 | B84: BELO HORIZONTE | C84: FFA BELO HORIZONTE | D84: 1002165 | E84: MANILHA DE CONCRETO 0,80 X 0,90 | F84: UN | G84: 160 | H84: 0 | I84: 68 | J84: 67 | K84: 1 | L84: 160
A85: 46192 | B85: BELO HORIZONTE | C85: FFA BELO HORIZONTE | D85: 1002168 | E85: MARCO DE CONCRETO TRIANGULAR | F85: UN | G85: 90 | H85: 0 | I85: 60 | J85: 53 | K85: 7 | L85: 630
A86: 46192 | B86: BELO HORIZONTE | C86: FFA BELO HORIZONTE | D86: 1002266 | E86: PLACA EM ALUMINIO 11X6,4 X 1MM | F86: UN | G86: 14 | H86: 0 | I86: 200 | J86: 100 | K86: 100 | L86: 1400
A87: 46192 | B87: BELO HORIZONTE | C87: FFA BELO HORIZONTE | D87: 1006872 | E87: TINTA ESMALTE AZUL 900ML | F87: PÇ | G87: 42.6 | H87: 0 | I87: 1 | J87: 0 | K87: 1 | L87: 42.6
A88: 46192 | B88: BELO HORIZONTE | C88: FFA BELO HORIZONTE | D88: 1002175 | E88: TINTA SPRAY BRANCA | F88: UN | G88: 21.66 | H88: 0 | I88: 5 | J88: 0 | K88: 5 | L88: 108.3
A89: 46192 | B89: BELO HORIZONTE | C89: FERRAMENTAL BH | D89: 1006884 | E89: ALFABETO CHAPA VAZADA 25MM | F89: UN | G89: 15.6747 | H89: 0 | I89: 26 | J89: 8 | K89: 18 | L89: 282.1446
A90: 46192 | B90: BELO HORIZONTE | C90: FERRAMENTAL BH | D90: 1006882 | E90: ALFABETO DE BATER 5MM | F90: UN | G90: 54.2 | H90: 0 | I90: 15 | J90: 9 | K90: 6 | L90: 325.2
... A134: 46192 | B134: BELO HORIZONTE | C134: FERRAMENTAL BH | D134: 1006886 | E134: TRINCHA VERMELHA 302 | F134: UN | G134: 2.9 | H134: 0 | I134: 10 | J134: 8 | K134: 2 | L134: 5.8

Sheet JUIZ DE FORA
A1: Data | B1: Base | C1: Projeto | D1: Código | E1: Descrição | F1: Unidade | G1: Valor Unitario | H1: Saldo Anterior | I1: Entradas | J1: Saidas | K1: Saldo | L1: Total Real
A2: 46192 | B2: JUIZ DE FORA | C2: FERRAMENTAL JUIZ DE | D2: 1006884 | E2: ALFABETO CHAPA VAZADA 25MM | F2: UN | G2: 15.6747 | H2: 0 | I2: 2 | J2: 0 | K2: 2 | L2: 31.3494
A3: 46192 | B3: JUIZ DE FORA | C3: FERRAMENTAL JUIZ DE | D3: 1006885 | E3: ALGARISMO CHAPA VAZADA | F3: UN | G3: 15.6753 | H3: 0 | I3: 2 | J3: 0 | K3: 2 | L3: 31.3506
A4: 46192 | B4: JUIZ DE FORA | C4: FERRAMENTAL JUIZ DE | D4: 1006827 | E4: CHAVE CANHAO 1/2 | F4: PÇ | G4: 19.99 | H4: 0 | I4: 27 | J4: 25 | K4: 2 | L4: 39.98
A5: 46192 | B5: JUIZ DE FORA | C5: FERRAMENTAL JUIZ DE | D5: 1006828 | E5: CHAVE CANHAO 1/4 | F5: PÇ | G5: 10.45 | H5: 0 | I5: 27 | J5: 25 | K5: 2 | L5: 20.9
A6: 46192 | B6: JUIZ DE FORA | C6: FERRAMENTAL JUIZ DE | D6: 1002103 | E6: CHAVE CANHAO 1/8 | F6: PÇ | G6: 23.95 | H6: 0 | I6: 15 | J6: 13 | K6: 2 | L6: 47.9
A7: 46192 | B7: JUIZ DE FORA | C7: FERRAMENTAL JUIZ DE | D7: 1006829 | E7: CHAVE CANHAO 3/16 | F7: PÇ | G7: 10.25 | H7: 0 | I7: 27 | J7: 25 | K7: 2 | L7: 20.5
A8: 46192 | B8: JUIZ DE FORA | C8: FERRAMENTAL JUIZ DE | D8: 1006839 | E8: CHAVE CANHAO 3/8 | F8: PÇ | G8: 14.45 | H8: 0 | I8: 25 | J8: 23 | K8: 2 | L8: 28.9
A9: 46192 | B9: JUIZ DE FORA | C9: FERRAMENTAL JUIZ DE | D9: 1006832 | E9: CHAVE CANHAO 7/32 | F9: PÇ | G9: 8.5 | H9: 0 | I9: 27 | J9: 25 | K9: 2 | L9: 17
A10: 46192 | B10: JUIZ DE FORA | C10: FERRAMENTAL JUIZ DE | D10: 1006843 | E10: CHAVE DE FENDA 1/4 | F10: PÇ | G10: 5.9 | H10: 0 | I10: 28 | J10: 25 | K10: 3 | L10: 17.7
A11: 46192 | B11: JUIZ DE FORA | C11: FERRAMENTAL JUIZ DE | D11: 1006844 | E11: CHAVE DE FENDA 1/8 | F11: PÇ | G11: 2.9 | H11: 0 | I11: 30 | J11: 27 | K11: 3 | L11: 8.7
A12: 46192 | B12: JUIZ DE FORA | C12: FERRAMENTAL JUIZ DE | D12: 1006845 | E12: CHAVE DE FENDA 3/16 | F12: PÇ | G12: 5.9 | H12: 0 | I12: 28 | J12: 26 | K12: 2 | L12: 11.8
A13: 46192 | B13: JUIZ DE FORA | C13: FERRAMENTAL JUIZ DE | D13: 1006846 | E13: CHAVE DE FENDA 5/16X10 | F13: PÇ | G13: 9.9 | H13: 0 | I13: 27 | J13: 25 | K13: 2 | L13: 19.8
... A66: 46192 | B66: JUIZ DE FORA FO J | C66: FFA JUIZ DE FORA | D66: 1006873 | E66: TINTA ESMALTE VERMELHA 900ML | F66: PÇ | G66: 42.6 | H66: 0 | I66: 1 | J66: 0 | K66: 1 | L66: 42.6

Sheet VARGINHA
A1: Data | B1: Base | C1: Projeto | D1: Código | E1: Descrição | F1: Unidade | G1: Valor Unitario | H1: Saldo Anterior | I1: Entradas | J1: Saidas | K1: Saldo | L1: Total Real
A2: 46192 | B2: VARGINHA | C2: FFA VARGINHA | D2: 1002163 | E2: CURVA AÇO GALVANIZADO PESADO 11/2" X 90º | F2: UN | G2: 23 | H2: 0 | I2: 3 | J2: 0 | K2: 3 | L2: 69
A3: 46192 | B3: VARGINHA | C3: FFA VARGINHA | D3: 1002162 | E3: ELETRODUTO AÇO GALV. A FOGO PESADO 11/2" X 3M | F3: UN | G3: 130 | H3: 0 | I3: 12 | J3: 0 | K3: 12 | L3: 1560
A4: 46192 | B4: VARGINHA | C4: FFA VARGINHA | D4: 1002164 | E4: LUVA AÇO GALVANIZADO PESADO 11/2" | F4: UN | G4: 12 | H4: 0 | I4: 6 | J4: 0 | K4: 6 | L4: 72
A5: 46192 | B5: VARGINHA | C5: FFA VARGINHA | D5: 1002168 | E5: MARCO DE CONCRETO TRIANGULAR | F5: UN | G5: 90 | H5: 0 | I5: 17 | J5: 6 | K5: 11 | L5: 990
A6: 46192 | B6: VARGINHA | C6: FFA VARGINHA | D6: 1002189 | E6: TINTA ESMALTE DE 3,6 VERMELHA | F6: LT | G6: 169 | H6: 0 | I6: 2 | J6: 1 | K6: 1 | L6: 169
A7: 46192 | B7: VARGINHA | C7: SSO VARGINHA | D7: 1001850 | E7: ANEL DE ANCORAGEM 1,50M | F7: PÇ | G7: 36.99 | H7: 0 | I7: 50 | J7: 45 | K7: 5 | L7: 184.95
A8: 46192 | B8: VARGINHA | C8: SSO VARGINHA | D8: 1006180 | E8: ANEL DE ANCORAGEM 2,00 MT | F8: UN | G8: 36.99 | H8: 0 | I8: 51 | J8: 45 | K8: 6 | L8: 221.94
A9: 46192 | B9: VARGINHA | C9: SSO VARGINHA | D9: 1000052 | E9: BANDEROLA DE SINALIZAÇÃO | F9: UND | G9: 10 | H9: 0 | I9: 58 | J9: 49 | K9: 9 | L9: 90
A10: 46192 | B10: VARGINHA | C10: SSO VARGINHA | D10: 1001864 | E10: BOLSA DE LONA PARA KIT LINHA DE VIDA | F10: UND | G10: 58 | H10: 0 | I10: 47 | J10: 41 | K10: 6 | L10: 348
A11: 46192 | B11: VARGINHA | C11: SSO VARGINHA | D11: 1001523 | E11: BOTA BORRACHA PVC 40 | F11: un | G11: 33.98 | H11: 0 | I11: 2 | J11: 0 | K11: 2 | L11: 67.96
A12: 46192 | B12: VARGINHA | C12: SSO VARGINHA | D12: 1000069 | E12: BOTA DE COURO SEM CADARÇO TAM. 39 | F12: PAR | G12: 54 | H12: 0 | I12: 20 | J12: 17 | K12: 3 | L12: 162
A13: 46192 | B13: VARGINHA | C13: SSO VARGINHA | D13: 1000070 | E13: BOTA DE COURO SEM CADARÇO TAM. 40 | F13: PAR | G13: 54 | H13: 0 | I13: 34 | J13: 32 | K13: 2 | L13: 108
... A43: 46192 | B43: VARGINHA | C43: SSO VARGINHA | D43: 1001923 | E43: JAQUETA CLARO COM CAPUZ - G | F43: UN | G43: 150 | H43: 0 | I43: 28 | J43: 26 | K43: 2 | L43: 300
A44: 46192 | B44: VARGINHA | C44: SSO VARGINHA | D44: 1000305 | E44: JUGULAR P/CAPACETE | F44: PÇ | G44: 34 | H44: 0 | I44: 68
A45: 46192 | B45: VARGINHA | C45: FERRAMENTAL VARGINHA | D45: 1006842 | E45: CHAVE BOCA/ESTRIA 1/2 | F45: PÇ | G45: 16 | H45: 0 | I45: 29 | J45: 25 | K45: 4 | L45: 64
A46: 46192 | B46: VARGINHA | C46: FERRAMENTAL VARGINHA | D46: 100120 | E46: CHAVE BOCA/ESTRIA 13MM | F46: UN | G46: 12.99 | H46: 0 | I46: 1 | J46: 0 | K46: 1 | L46: 12.99
A47: 46192 | B47: VARGINHA | C47: FERRAMENTAL VARGINHA | D47: 1006835 | E47: CHAVE BOCA/ESTRIA 3/8 | F47: PÇ | G47: 9.85 | H47: 0 | I47: 36 | J47: 31 | K47: 5 | L47: 49.25
A48: 46192 | B48: VARGINHA | C48: FERRAMENTAL VARGINHA | D48: 1006836 | E48: CHAVE BOCA/ESTRIA 5/16 | F48: PÇ | G48: 10.2 | H48: 0 | I48: 31 | J48: 29 | K48: 2 | L48: 20.4
A49: 46192 | B49: VARGINHA | C49: FERRAMENTAL VARGINHA | D49: 1006837 | E49: CHAVE BOCA/ESTRIA 7/16 | F49: PÇ | G49: 5.9 | H49: 0 | I49: 30 | J49: 26 | K49: 4 | L49: 23.6
A50: 46192 | B50: VARGINHA | C50: FERRAMENTAL VARGINHA | D50: 1006827 | E50: CHAVE CANHAO 1/2 | F50: PÇ | G50: 19.99 | H50: 0 | I50: 40 | J50: 37 | K50: 3 | L50: 59.97
A51: 46192 | B51: VARGINHA | C51: FERRAMENTAL VARGINHA | D51: 1006828 | E51: CHAVE CANHAO 1/4 | F51: PÇ | G51: 10.45 | H51: 0 | I51: 47 | J51: 41 | K51: 6 | L51: 62.7
A52: 46192 | B52: VARGINHA | C52: FERRAMENTAL VARGINHA | D52: 1002103 | E52: CHAVE CANHAO 1/8 | F52: PÇ | G52: 23.95 | H52: 0 | I52: 35 | J52: 34 | K52: 1 | L52: 23.95
A53: 46192 | B53: VARGINHA | C53: FERRAMENTAL VARGINHA | D53: 1006829 | E53: CHAVE CANHAO 3/16 | F53: PÇ | G53: 10.25 | H53: 0 | I53: 49 | J53: 43 | K53: 6 | L53: 61.5
A54: 46192 | B54: VARGINHA | C54: FERRAMENTAL VARGINHA | D54: 1006950 | E54: CHAVE CANHAO 5MM | F54: UN | G54: 12.37 | H54: 0 | I54: 2 | J54: 0 | K54: 2 | L54: 24.74
